Workbook

Sheet Parts
A1: Part_ID | B1: Category | C1: Description | D1: Value_Rating | E1: Package_Footprint | F1: Manufacturer | G1: MPN | H1: Found_In | I1: KiCad_References | J1: Source | K1: Review_Status | L1: Notes | M1: Duplicate_Check_Key
A2: ENP-00001 | B2: Kabelsatz | C2: Set, SET JST-PH 4-polig 2.00mm vertikaler PCB-Stecker, Buchse THT | D2: JST-PH, 4-polig, Set | F2: JST | H2: EnvNode | I2: GPIO's | J2: BOM_Mainboard.xlsx | K2: OK | L2: GPIO-Anschlüsse; exakte Herstellerartikelnummer vor Bestellung gegen Footprint und Orientierung prüfen Set-Inhalt gegenüber dem separat aus KiCad abgeleiteten PCB-Header prüfen. | M2: SET, SET JST-PH 4-POLIG 2.00MM VERTIKALER PCB-STECKER, BUCHSE THT| | S2: =IF(G2<>"",UPPER(TRIM(G2)),UPPER(TRIM(C2&"|"&E2))) -> SET, SET JST-PH 4-POLIG 2.00MM VERTIKALER PCB-STECKER, BUCHSE THT|
A3: ENP-00002 | B3: Kabelsatz | C3: Qwiic/JST-SH, 4-poliges Pigtail JST | D3: JST-SH/Qwiic, 4-polig | F3: JST | H3: EnvNode | I3: I2CA0 1-3 I2C1 1-3 | J3: BOM_Mainboard.xlsx | K3: OK | L3: Qwiic-Konvention: GND=schwarz, 3V3=rot, SDA=blau, SCL=gelb; Kabelbelegung vor Anschluss prüfen Pigtail ist ein Beschaffungsartikel und nicht der PCB-Steckverbinder. | M3: QWIIC/JST-SH, 4-POLIGES PIGTAIL JST| | S3: =IF(G3<>"",UPPER(TRIM(G3)),UPPER(TRIM(C3&"|"&E3))) -> QWIIC/JST-SH, 4-POLIGES PIGTAIL JST|
A4: ENP-00003 | B4: Steckverbinder | C4: PinSocket 1x4, 2.54 mm | D4: 1x4, 2,54 mm | E4: PinSocket_1x04_P2.54mm_Vertical | F4: fischer Elektronik | G4: 10120946 | H4: EnvNode; RainDetector | I4: EnvNode I2C0_4,I2C1_4; RainDetector J3,J4 | J4: BOM_Mainboard.xlsx | K4: OK | L4: Für interne Qwiic-Breakouts; Bauhöhe und Ausführung passend zur Mechanik wählen | M4: 10120946 | S4: =IF(G4<>"",UPPER(TRIM(G4)),UPPER(TRIM(C4&"|"&E4))) -> 10120946
A5: ENP-00004 | B5: Steckverbinder | C5: PinSocket 1x20, 2.54mm, cut to 19 Pins | D5: 1x20, 2,54 mm, trennbar | F5: fischer Elektronik | G5: BL1.20 G | H5: EnvNode | I5: ESP32 | J5: BOM_Mainboard.xlsx | K5: OK | L5: Für ESP32-DevKitC mit 38 Pins; alternativ eine geeignete 38-Pin-ESP32-Fassung verwenden | M5: BL1.20 G | S5: =IF(G5<>"",UPPER(TRIM(G5)),UPPER(TRIM(C5&"|"&E5))) -> BL1.20 G
A6: ENP-00005 | B6: Widerstand | C6: 4.7 kOhm 1% SMD 1206 | D6: 4,7 kΩ, 1 %, 250 mW | E6: Resistor_SMD:R_1206_3216Metric_Pad1.30x1.75mm_HandSolder | F6: Vishay | G6: CRCW12064K70FKEA | H6: EnvNode; EnvNodeMini Rev 0.2; AnalogInput Rev 0.1; AnalogHydroPressure | I6: EnvNode R1-R4; EnvNodeMini Rev 0.2 R1-R4; AnalogInput Rev 0.1 R2; AnalogHydroPressure R2 | J6: BOM_Mainboard.xlsx | K6: OK | L6: I2C-Pull-ups für die beiden I2C-Busse | M6: CRCW12064K70FKEA | S6: =IF(G6<>"",UPPER(TRIM(G6)),UPPER(TRIM(C6&"|"&E6))) -> CRCW12064K70FKEA
A7: ENP-00006 | B7: Kondensator | C7: 100 nF Keramik SMD | D7: 100 nF, 10 %, X7R, 100 V | E7: Capacitor_SMD:C_1206_3216Metric_Pad1.33x1.80mm_HandSolder | F7: Kyocera | G7: C1206F104K1RACTU | H7: EnvNode; EnvNodeMini Rev 0.2; AnalogHydroPressure; RainDetector; SolarRadiation; Empty FullSize/HalfSize SMD/THT; DuoRelay Rev 0.2 | I7: EnvNode C3,C4; EnvNodeMini Rev 0.2 C1,C4,C5; AnalogHydroPressure C1,C3,C8; RainDetector C1; SolarRadiation C1; Empty-Boards C1; DuoRelay Rev 0.2 C1 | J7: BOM_Mainboard.xlsx | K7: OK | L7: Spannungsfestigkeit, Dielektrikum und Bauform vor Bestellung gegen Schaltplan und Footprint prüfen; C1 ist in allen vier aktuellen Empty-Schemata derzeit DNP; C1 ist im aktuellen DuoRelay-Schema derzeit DNP | M7: C1206F104K1RACTU | S7: =IF(G7<>"",UPPER(TRIM(G7)),UPPER(TRIM(C7&"|"&E7))) -> C1206F104K1RACTU
A8: ENP-00007 | B8: Kondensator | C8: 10 uF Keramik SMD | D8: 10 µF, 25 V, X7R | E8: Capacitor_SMD:C_1206_3216Metric_Pad1.33x1.80mm_HandSolder | F8: Kyocera AVX | G8: 12063C106KAT2A | H8: EnvNode; EnvNodeMini Rev 0.2 | I8: EnvNode C1; EnvNodeMini Rev 0.2 C2 | J8: BOM_Mainboard.xlsx | K8: OK | L8: Spannungsfestigkeit, Dielektrikum und Bauform vor Bestellung gegen Schaltplan und Footprint prüfen | M8: 12063C106KAT2A | S8: =IF(G8<>"",UPPER(TRIM(G8)),UPPER(TRIM(C8&"|"&E8))) -> 12063C106KAT2A
A9: ENP-00008 | B9: Kondensator | C9: 47 uF 10V Tantal | D9: 47 µF, 10 V | E9: Capacitor_Tantalum_SMD:CP_EIA-3528-21_Kemet-B | F9: Kyocera AVX | G9: TAJB476K010RNJ | H9: EnvNode; EnvNodeMini Rev 0.2 | I9: EnvNode C2; EnvNodeMini Rev 0.2 C3 | J9: BOM_Mainboard.xlsx | K9: OK | L9: Polarisiert; Bauform B | M9: TAJB476K010RNJ | S9: =IF(G9<>"",UPPER(TRIM(G9)),UPPER(TRIM(C9&"|"&E9))) -> TAJB476K010RNJ
A10: ENP-00009 | B10: Spannungsregler | C10: LDO 3.3V SOT-223 | D10: 3,3 V, 1 A | E10: Package_TO_SOT_SMD:SOT-223-3_TabPin2 | F10: Texas Instruments | G10: LM3940IMP-3.3/NOPB | H10: EnvNode; EnvNodeMini Rev 0.2 | I10: EnvNode U1; EnvNodeMini Rev 0.2 U3 | J10: BOM_Mainboard.xlsx | K10: OK | L10: Footprint und thermische Auslegung vor Bestückung prüfen | M10: LM3940IMP-3.3/NOPB | S10: =IF(G10<>"",UPPER(TRIM(G10)),UPPER(TRIM(C10&"|"&E10))) -> LM3940IMP-3.3/NOPB
A11: ENP-00010 | B11: Entwicklungsmodul | C11: ESP32-DevKitC | D11: 38 Pin | E11: PCM_Espressif:ESP32-DevKitC | F11: Espressif Systems | H11: EnvNode; EnvNodeMini Rev 0.2 | I11: EnvNode U2; EnvNodeMini Rev 0.2 U1 | J11: BOM_Mainboard.xlsx | K11: OK | L11: Exakte Modulvariante und Pinout vor Bestückung prüfen Hersteller/MPN aus verschobenen Altdaten korrigiert; genaue DevKitC-Variante fehlt. | M11: ESP32-DEVKITC|PCM_ESPRESSIF:ESP32-DEVKITC | S11: =IF(G11<>"",UPPER(TRIM(G11)),UPPER(TRIM(C11&"|"&E11))) -> ESP32-DEVKITC|PCM_ESPRESSIF:ESP32-DEVKITC
A12: ENP-00011 | B12: PCB | C12: EnvNode Mainboard Rev 0.1 | D12: Revision 0.1 | F12: JLCPCB | H12: EnvNode | J12: BOM_Mainboard.xlsx | K12: OK | L12: Unbestückte Leiterplatte; SMD-Lötjumper sind PCB-Strukturen und keine Kaufteile Historische PCB-Revision; aktueller KiCad-Stand ist Revision 0.2. | M12: ENVNODE MAINBOARD REV 0.1| | S12: =IF(G12<>"",UPPER(TRIM(G12)),UPPER(TRIM(C12&"|"&E12))) -> ENVNODE MAINBOARD REV 0.1|
A13: ENP-00012 | B13: Steckverbinder | C13: JST - Stiftleiste, gerade, 1x2-polig - PH | D13: JST-PH, 2-polig, 2,00 mm | E13: Connector_JST:JST_PH_B2B-PH-K_1x02_P2.00mm_Vertical | F13: JST | G13: B2B-PH-K-S | H13: EnvNode; EnvNodeMini Rev 0.2 | I13: EnvNode J1; EnvNodeMini Rev 0.2 J1 | J13: BOM_Mainboard.xlsx | K13: OK | M13: B2B-PH-K-S | S13: =IF(G13<>"",UPPER(TRIM(G13)),UPPER(TRIM(C13&"|"&E13))) -> B2B-PH-K-S
A14: ENP-00013 | B14: MOSFET | C14: MOSFET, N-Ch 30V 5,7A 0,018R, SOT-23 | D14: N-Kanal, 30 V, 5,7 A | E14: Package_TO_SOT_SMD:SOT-23 | F14: Alpha&Omega Semiconductor | G14: AO3400A | H14: RainDetector | I14: Q1 | J14: BOM_Mainboard.xlsx | K14: OK | M14: AO3400A | S14: =IF(G14<>"",UPPER(TRIM(G14)),UPPER(TRIM(C14&"|"&E14))) -> AO3400A
A15: ENP-00014 | B15: Sensormodul | C15: Arduino - Temperatur- & Feuchtigkeitssensor, SHTC3 | D15: SHTC3 Breakout | F15: Soldered | G15: 333032 | H15: Sensor | J15: BOM_Mainboard.xlsx | K15: OK | M15: 333032 | S15: =IF(G15<>"",UPPER(TRIM(G15)),UPPER(TRIM(C15&"|"&E15))) -> 333032
A16: ENP-00015 | B16: Entwicklungsmodul | C16: Entwicklerboards - ADC, 4 Kanal, 16-Bit, ADS1115 | D16: ADS1115 Breakout, 4 Kanal, 16 Bit | F16: Soldered | G16: 333095 | H16: A/D Wandler | J16: BOM_Mainboard.xlsx | K16: OK | M16: 333095 | S16: =IF(G16<>"",UPPER(TRIM(G16)),UPPER(TRIM(C16&"|"&E16))) -> 333095
A17: ENP-00016 | B17: Widerstand | C17: SMD-Widerstand, 1206, 100 kOhm, 250 mW, 0,1% | D17: 100 kΩ, 0,1 %, 250 mW | E17: Resistor_SMD:R_1206_3216Metric_Pad1.30x1.75mm_HandSolder | F17: Panasonic | G17: ERA8AEB104V | H17: RainDetector; DuoRelay; AnalogHydroPressure | I17: RainDetector R2,R4; DuoRelay R3,R4; AnalogHydroPressure R7 | J17: BOM_Mainboard.xlsx | K17: OK | L17: Lieferanten-Bestellnummer in der Altdatei enthält vermischte Angaben. | M17: ERA8AEB104V | S17: =IF(G17<>"",UPPER(TRIM(G17)),UPPER(TRIM(C17&"|"&E17))) -> ERA8AEB104V
A18: ENP-00017 | B18: Widerstand | C18: SMD-Widerstand, 1206, 100 Ohm, 250 mW, 5% | D18: 100 Ω, 5 %, 250 mW | E18: Resistor_SMD:R_1206_3216Metric_Pad1.30x1.75mm_HandSolder | F18: YAGEO | G18: RC1206JR-07100RL | H18: RainDetector; SolarRadiation | I18: RainDetector R1; SolarRadiation R2 | J18: BOM_Mainboard.xlsx | K18: OK | M18: RC1206JR-07100RL | S18: =IF(G18<>"",UPPER(TRIM(G18)),UPPER(TRIM(C18&"|"&E18))) -> RC1206JR-07100RL
A19: ENP-00018 | B19: Widerstand | C19: SMD-Widerstand, 1206, 10 kOhm, 250 mW, 0,1% | D19: 10 kΩ, 0,1 %, 250 mW | E19: Resistor_SMD:R_1206_3216Metric_Pad1.30x1.75mm_HandSolder | F19: Panasonic | G19: ERA8AEB103V | H19: RainDetector | I19: R3 | J19: BOM_Mainboard.xlsx | K19: OK | L19: Offensichtlich zusammengesetzte MPN aus Altdaten normalisiert. | M19: ERA8AEB103V | S19: =IF(G19<>"",UPPER(TRIM(G19)),UPPER(TRIM(C19&"|"&E19))) -> ERA8AEB103V
A20: ENP-00019 | B20: Steckverbinder | C20: Stiftleiste, 8-polig, Raster 2,54mm | D20: 1x8, 2,54 mm | E20: Connector_PinHeader_2.54mm:PinHeader_1x08_P2.54mm_Vertical | F20: BKL Electronic | G20: 10120505 | H20: RainDetector | I20: J1,J2 | J20: BOM_Mainboard.xlsx | K20: OK | M20: 10120505 | S20: =IF(G20<>"",UPPER(TRIM(G20)),UPPER(TRIM(C20&"|"&E20))) -> 10120505
A21: ENP-00020 | B21: IC | C21: Timer-IC, Typ 555, SO-8 | D21: CMOS 555 | E21: Package_SO:SOIC-8_3.9x4.9mm_P1.27mm | F21: Renesas | G21: ICM7555IBAZ | H21: RainDetector | I21: U1 | J21: BOM_Mainboard.xlsx | K21: OK | M21: ICM7555IBAZ | S21: =IF(G21<>"",UPPER(TRIM(G21)),UPPER(TRIM(C21&"|"&E21))) -> ICM7555IBAZ
A22: ENP-00021 | B22: Steckverbinder | C22: PinSocket 1x8, 2,54mm SMD | D22: 1x8, 2,54 mm, SMD | F22: fischer Elektronik | G22: BL 3 8 G | H22: Stall.biz/Weatherman-Detektorplatine | I22: Mechanischer Gegenstecker zu RainDetector J1/J2; nicht im RainDetector-KiCad geführt | J22: BOM_Mainboard.xlsx; Nutzerklärung 2026-09-01 | K22: OK | L22: 1×8-SMD-Buchsenleiste sitzt physisch auf der Stall.biz/Weatherman-Detektorplatine. Auf der RainDetector-Platine werden für J1/J2 die 1×8-THT-Stiftleisten ENP-00019 bestückt. | M22: BL 3 8 G | S22: =IF(G22<>"",UPPER(TRIM(G22)),UPPER(TRIM(C22&"|"&E22))) -> BL 3 8 G
A23: ENP-00022 | B23: Widerstand | C23: SMD-Widerstand, 1206, 47 Ohm, 250 mW, 5% | D23: 47 Ω | E23: Resistor_SMD:R_1206_3216Metric_Pad1.30x1.75mm_HandSolder | F23: RND components | G23: RND 1551206S4J0470T5E | H23: Detector | J23: BOM_Mainboard.xlsx | K23: OK | M23: RND 1551206S4J0470T5E | S23: =IF(G23<>"",UPPER(TRIM(G23)),UPPER(TRIM(C23&"|"&E23))) -> RND 1551206S4J0470T5E
A24: ENP-00023 | B24: Relais | C24: Steck-Printrelais, 1 CO, 6 A, 5 V DC sensitiv | D24: 5 V, 1 Wechsler, 6 A | E24: Relay_THT:Relay_SPDT_Finder_34.51_Vertical | F24: finder | G24: 34.51.7.005.0010 | H24: DuoRelay | I24: K1,K2 | J24: BOM_Mainboard.xlsx | K24: OK | M24: 34.51.7.005.0010 | S24: =IF(G24<>"",UPPER(TRIM(G24)),UPPER(TRIM(C24&"|"&E24))) -> 34.51.7.005.0010
A25: ENP-00024 | B25: IC | C25: I²C-EEPROM 2 Kbit mit vorprogrammierter EUI-64 und zwei Adresspins | D25: 2 Kbit, I²C, EUI-64, A0/A1, 1,7–5,5 V | E25: Package_TO_SOT_SMD:SOT-23-6 | F25: Microchip Technology | G25: 24AA025E64T-I/OT | H25: EnvNode; EnvNodeMini Rev 0.2; Empty FullSize/HalfSize SMD/THT; DuoRelay; AnalogHydroPressure | I25: EnvNode U3; EnvNodeMini Rev 0.2 U2; Empty-Boards U1; DuoRelay U1; AnalogHydroPressure U1 | J25: KiCad; Microchip datasheet DS20002124G; DigiKey Produktseite, abgerufen 2026-09-02 | K25: OK | L25: Gemeinsamer Identifikations-EEPROM für alle Boards. Frühere Lieferantendaten gehörten zur falschen SPI-Version 25AA02E64T-I/OT und wurden entfernt; Bezugsquelle, Bestellnummer und Preis neu ergänzen. Auf Modulboards derzeit DNP.; In allen vier aktuellen Empty-Schemata derzeit DNP; A1 liegt an +3V3_SYS, A0 wird über J1 herausgeführt; U1 ist in den aktuellen DuoRelay- und AnalogHydroPressure-Schemata derzeit DNP Bezug als Cut Tape bei DigiKey; keine parametrischen Ersatztypen ohne vorprogrammierte EUI-64 verwenden. | M25: 24AA025E64T-I/OT | S25: =IF(G25<>"",UPPER(TRIM(G25)),UPPER(TRIM(C25&"|"&E25))) -> 24AA025E64T-I/OT
A26: ENP-00025 | B26: Steckverbinder | C26: JST-PH Stiftleiste, 4-polig, vertikal | D26: 4-polig, 2,00 mm | E26: Connector_JST:JST_PH_B4B-PH-K_1x04_P2.00mm_Vertical | F26: JST | G26: B4B-PH-K-S | H26: EnvNode | I26: GPIO4, GPIO13-19, GPIO23, GPIO32-36, GPIO39 | J26: KiCad | K26: OK | L26: Mögliche Überschneidung mit dem vorhandenen JST-PH-Set prüfen. | M26: B4B-PH-K-S | S26: =IF(G26<>"",UPPER(TRIM(G26)),UPPER(TRIM(C26&"|"&E26))) -> B4B-PH-K-S
A27: ENP-00026 | B27: Steckverbinder | C27: JST-SH Stiftleiste, 4-polig, horizontal | D27: 4-polig, 1,00 mm | E27: Connector_JST:JST_SH_SM04B-SRSS-TB_1x04-1MP_P1.00mm_Horizontal | F27: JST | G27: SM04B-SRSS-TB | H27: EnvNode; EnvNodeMini Rev 0.2; SolarRadiation | I27: EnvNode I2C0_1-3,I2C1_1-3; EnvNodeMini Rev 0.2 J4,J5; SolarRadiation I2C1 | J27: KiCad | K27: OK | L27: MPN-Suffix und Verpackungsform festlegen; nicht mit Qwiic-Pigtail zusammenführen. | M27: SM04B-SRSS-TB | S27: =IF(G27<>"",UPPER(TRIM(G27)),UPPER(TRIM(C27&"|"&E27))) -> SM04B-SRSS-TB
A28: ENP-00027 | B28: IC | C28: 16-Bit ADC mit I²C | D28: ADS1115IDGS | E28: Package_SO:TSSOP-10_3x3mm_P0.5mm | F28: Texas Instruments | G28: ADS1115IDGS | H28: AnalogInput; SolarRadiation; AnalogHydroPressure | I28: jeweils U1; AnalogHydroPressure U2 | J28: KiCad | K28: OK | L28: Nicht mit dem vorhandenen ADS1115-Entwicklungsboard zusammenführen. | M28: ADS1115IDGS | S28: =IF(G28<>"",UPPER(TRIM(G28)),UPPER(TRIM(C28&"|"&E28))) -> ADS1115IDGS
A29: ENP-00028 | B29: Kondensator | C29: Keramikkondensator 1 µF SMD | D29: 1 µF | E29: Capacitor_SMD:C_1206_3216Metric_Pad1.33x1.80mm_HandSolder | F29: Kyocera | G29: 12065C105JAT2A | H29: AnalogInput; AnalogHydroPressure | I29: C1; AnalogHydroPressure C4,C7 | J29: KiCad | K29: OK | M29: 12065C105JAT2A | S29: =IF(G29<>"",UPPER(TRIM(G29)),UPPER(TRIM(C29&"|"&E29))) -> 12065C105JAT2A
A30: ENP-00029 | B30: Diode | C30: Dual-Schottky-Diode BAT54S | D30: BAT54S | E30: Package_TO_SOT_SMD:SOT-23 | F30: Diotec | G30: BAT54S | H30: AnalogInput; AnalogHydroPressure | I30: D1; AnalogHydroPressure D1 | J30: KiCad | K30: OK | L30: Aktuelles AnalogHydroPressure verwendet SOT-23 und stimmt damit mit dem Artikel-Footprint überein; Gehäuse der bestellten Variante dennoch prüfen. | M30: BAT54S | S30: =IF(G30<>"",UPPER(TRIM(G30)),UPPER(TRIM(C30&"|"&E30))) -> BAT54S
A31: ENP-00030 | B31: Steckverbinder | C31: Buchsenleiste 2x4, vertikal | D31: 2x4, 2,54 mm | E31: PinSocket_2x04_P2.54mm_Vertical / EnvNode Bottom-Variante | H31: Legacy Rev 0.1: EnvNodeMini; AnalogInput; DuoRelay | I31: AnalogInput J1,J2; DuoRelay J1,J2; EnvNodeMini J1,J2,J4,J5 | J31: KiCad | K31: Legacy | L31: Legacy-Artikel für die Modulsteckverbindung Rev 0.1; nicht für die aktuellen 2x7-Steckplätze verwenden. | M31: BUCHSENLEISTE 2X4, VERTIKAL|PINSOCKET_2X04_P2.54MM_VERTICAL / ENVNODE BOTTOM-VARIANTE | S31: =IF(G31<>"",UPPER(TRIM(G31)),UPPER(TRIM(C31&"|"&E31))) -> BUCHSENLEISTE 2X4, VERTIKAL|PINSOCKET_2X04_P2.54MM_VERTICAL / ENVNODE BOTTOM-VARIANTE
A32: ENP-00031 | B32: Steckverbinder | C32: Buchsenleiste 1x2, vertikal | D32: 1x2, 2,54 mm | E32: Connector_PinSocket_2.54mm:PinSocket_1x02_P2.54mm_Vertical | H32: AnalogInput; AnalogHydroPressure | I32: J3; AnalogHydroPressure J3 | J32: KiCad | K32: Legacy | M32: BUCHSENLEISTE 1X2, VERTIKAL|CONNECTOR_PINSOCKET_2.54MM:PINSOCKET_1X02_P2.54MM_VERTICAL | S32: =IF(G32<>"",UPPER(TRIM(G32)),UPPER(TRIM(C32&"|"&E32))) -> BUCHSENLEISTE 1X2, VERTIKAL|CONNECTOR_PINSOCKET_2.54MM:PINSOCKET_1X02_P2.54MM_VERTICAL
A33: ENP-00032 | B33: Widerstand | C33: Widerstand, Metallschicht, 150 Ohm, 0207, 250 mW, 0,1% | D33: 150 Ω, 0,1 %, ≤25 ppm/K, >0,125 W | E33: Resistor_THT:R_Axial_DIN0207_L6.3mm_D2.5mm_P7.62mm_Horizontal | F33: Arcol | G33: MRA0207 150R B 15PPM TA | H33: AnalogInput; AnalogHydroPressure | I33: R1; AnalogHydroPressure R3 | J33: KiCad | K33: OK | M33: MRA0207 150R B 15PPM TA | S33: =IF(G33<>"",UPPER(TRIM(G33)),UPPER(TRIM(C33&"|"&E33))) -> MRA0207 150R B 15PPM TA
A34: ENP-00033 | B34: Diode | C34: Schnelle Schaltdiode 1N4148W | D34: 1N4148W | E34: Diode_SMD:D_SOD-123 | F34: Diotec | G34: 1N4148W | H34: DuoRelay | I34: D1,D2 | J34: KiCad | K34: OK | M34: 1N4148W | S34: =IF(G34<>"",UPPER(TRIM(G34)),UPPER(TRIM(C34&"|"&E34))) -> 1N4148W
A35: ENP-00034 | B35: Steckverbinder | C35: Schraubklemme 1x3, horizontal | D35: 3-polig, 5,08 mm | E35: TerminalBlock_Phoenix:TerminalBlock_Phoenix_MKDS-3-3-5.08_1x03_P5.08mm_Horizontal | F35: Phoenix Contact | H35: DuoRelay | I35: J3,J4 | J35: KiCad | K35: OK | L35: Exakte Hersteller-MPN ergänzen. | M35: SCHRAUBKLEMME 1X3, HORIZONTAL|TERMINALBLOCK_PHOENIX:TERMINALBLOCK_PHOENIX_MKDS-3-3-5.08_1X03_P5.08MM_HORIZONTAL | S35: =IF(G35<>"",UPPER(TRIM(G35)),UPPER(TRIM(C35&"|"&E35))) -> SCHRAUBKLEMME 1X3, HORIZONTAL|TERMINALBLOCK_PHOENIX:TERMINALBLOCK_PHOENIX_MKDS-3-3-5.08_1X03_P5.08MM_HORIZONTAL
A36: ENP-00035 | B36: Transistor | C36: NPN-Transistor BC817 | D36: BC817 | E36: Package_TO_SOT_SMD:SOT-23_Handsoldering | F36: Diotec | G36: BC817 | H36: DuoRelay | I36: Q1,Q2 | J36: KiCad | K36: OK | M36: BC817 | S36: =IF(G36<>"",UPPER(TRIM(G36)),UPPER(TRIM(C36&"|"&E36))) -> BC817
A37: ENP-00036 | B37: Widerstand | C37: Widerstand 1 kΩ SMD | D37: 1 kΩ | E37: Resistor_SMD:R_1206_3216Metric_Pad1.30x1.75mm_HandSolder | F37: Vishay | G37: CRCW12061K00FKEA | H37: DuoRelay | I37: R1,R2 | J37: KiCad | K37: OK | M37: CRCW12061K00FKEA | S37: =IF(G37<>"",UPPER(TRIM(G37)),UPPER(TRIM(C37&"|"&E37))) -> CRCW12061K00FKEA
A38: ENP-00037 | B38: Kondensator | C38: Elektrolytkondensator 47 µF radial | D38: 47 µF, 50 V | E38: Capacitor_SMD:CP_Elec_6.3x7.7 | F38: Europe ChemiCon | G38: HHXC500ARA470MHA0G | H38: EnvNodeMini Rev 0.1 | I38: EnvNodeMini Rev 0.1 C1 | J38: KiCad | K38: OK | M38: HHXC500ARA470MHA0G | S38: =IF(G38<>"",UPPER(TRIM(G38)),UPPER(TRIM(C38&"|"&E38))) -> HHXC500ARA470MHA0G
A39: ENP-00038 | B39: Diode | C39: Schottky-Diode STPS3L60S | D39: B360B-13-F | E39: Diode_SMD:D_SMB_Handsoldering | F39: Diodes | G39: STPS3L60S | H39: EnvNodeMini Rev 0.1 | I39: EnvNodeMini Rev 0.1 D1 | J39: KiCad | K39: OK | M39: STPS3L60S | S39: =IF(G39<>"",UPPER(TRIM(G39)),UPPER(TRIM(C39&"|"&E39))) -> STPS3L60S
A40: ENP-00039 | B40: Schutzdiode | C40: TVS-Diode SMBJ24A | D40: 24 V | E40: Diode_SMD:D_SMB_Handsoldering | F40: Littelfuse | G40: SMBJ24A | H40: EnvNodeMini Rev 0.1 | I40: EnvNodeMini Rev 0.1 D2 | J40: KiCad | K40: OK | M40: SMBJ24A | S40: =IF(G40<>"",UPPER(TRIM(G40)),UPPER(TRIM(C40&"|"&E40))) -> SMBJ24A
...

Sheet Kits
A1: Kit_ID | B1: Kit_Name | C1: Revision | D1: Status | E1: KiCad_Schematic | F1: KiCad_PCB | G1: Notes
A2: ENK-00001 | B2: EnvNode Mini Bausatz | C2: 0.2 | D2: Entwurf | E2: hardware/kicad/MainBoards/EnvNode Mini/EnvNode Mini.kicad_sch | F2: hardware/kicad/MainBoards/EnvNode Mini/EnvNode Mini.kicad_pcb | G2: Elektronischer Grundumfang vollständig aus aktuellem KiCad-Stand übernommen. Externe 5-V-Zuführung, Pigtail und weitere Montagekomponenten werden anschließend ergänzt.
A3: ENK-00002 | B3: DuoRelay FullSize Bausatz | C3: 0.2 | D3: Entwurf | E3: hardware/kicad/Modules/FullSize/DuoRelay/DuoRelay.kicad_sch | F3: hardware/kicad/Modules/FullSize/DuoRelay/DuoRelay.kicad_pcb | G3: Aktueller bestückter KiCad-Umfang plus PCB; DNP-Positionen enthalten und als DNP gekennzeichnet. Mechanische Zusatzteile können anschließend ergänzt werden.
A4: ENK-00003 | B4: AnalogHydroPressure FullSize Bausatz | C4: 0.2 | D4: Entwurf | E4: hardware/kicad/Modules/FullSize/AnalogHydroPressure/AnalogHydroPressure.kicad_sch | F4: hardware/kicad/Modules/FullSize/AnalogHydroPressure/AnalogHydroPressure.kicad_pcb | G4: Aktueller bestückter KiCad-Umfang einschließlich Busumschaltung plus PCB; DNP-Positionen enthalten und als DNP gekennzeichnet. Mechanische Zusatzteile können anschließend ergänzt werden.
A5: ENK-00004 | B5: RainDetector Bausatz | C5: 1.0 | D5: Entwurf | E5: hardware/kicad/Sensors/Raindetector/Raindetector.kicad_sch | F5: hardware/kicad/Sensors/Raindetector/Raindetector.kicad_pcb | G5: Aktueller bestückter KiCad-Umfang plus PCB. Stall.biz/Weatherman-Detektorplatine und deren 1×8-SMD-Buchsenleisten ENP-00021 gehören zur Gegenseite und sind nicht Bestandteil dieses Kits. Keine DNP-Positionen.

Sheet Kit_BOM
A1: Kit_ID | B1: Kit_Revision | C1: Position | D1: RefDes | E1: Part_Number | F1: Quantity | G1: Build_Status | H1: Source_Type | I1: Value | J1: Footprint | K1: Unit_Price_EUR | L1: Position_Price_EUR | M1: Notes
A2: ENK-00001 | B2: 0.2 | C2: 10 | D2: C1 | E2: ENP-00006 | F2: 1 | G2: Bestücken | H2: KiCad | I2: =IFERROR(VLOOKUP(E2,Parts!$A$2:$S$200,4,FALSE()),"") -> 100 nF, 10 %, X7R, 100 V | J2: =IFERROR(VLOOKUP(E2,Parts!$A$2:$S$200,5,FALSE()),"") -> Capacitor_SMD:C_1206_3216Metric_Pad1.33x1.80mm_HandSolder | K2: =SUMIFS(Part_Suppliers!$E$2:$E$300,Part_Suppliers!$A$2:$A$300,$E2,Part_Suppliers!$H$2:$H$300,"Ja") -> 0.24 | L2: =F2*K2 -> 0.24 | M2: =IFERROR(VLOOKUP($E2,Parts!$A$2:$M$200,12,FALSE()),"") -> Spannungsfestigkeit, Dielektrikum und Bauform vor Bestellung gegen Schaltplan und Footprint prüfen; C1 ist in allen vier aktuellen Empty-Schemata derzeit DNP; C1 ist im aktuellen DuoRelay-Schema derzeit DNP
A3: ENK-00001 | B3: 0.2 | C3: 20 | D3: C2 | E3: ENP-00007 | F3: 1 | G3: Bestücken | H3: KiCad | I3: =IFERROR(VLOOKUP(E3,Parts!$A$2:$S$200,4,FALSE()),"") -> 10 µF, 25 V, X7R | J3: =IFERROR(VLOOKUP(E3,Parts!$A$2:$S$200,5,FALSE()),"") -> Capacitor_SMD:C_1206_3216Metric_Pad1.33x1.80mm_HandSolder | K3: =SUMIFS(Part_Suppliers!$E$2:$E$300,Part_Suppliers!$A$2:$A$300,$E3,Part_Suppliers!$H$2:$H$300,"Ja") -> 0.11 | L3: =F3*K3 -> 0.11 | M3: =IFERROR(VLOOKUP($E3,Parts!$A$2:$M$200,12,FALSE()),"") -> Spannungsfestigkeit, Dielektrikum und Bauform vor Bestellung gegen Schaltplan und Footprint prüfen
A4: ENK-00001 | B4: 0.2 | C4: 30 | D4: C3 | E4: ENP-00008 | F4: 1 | G4: Bestücken | H4: KiCad | I4: =IFERROR(VLOOKUP(E4,Parts!$A$2:$S$200,4,FALSE()),"") -> 47 µF, 10 V | J4: =IFERROR(VLOOKUP(E4,Parts!$A$2:$S$200,5,FALSE()),"") -> Capacitor_Tantalum_SMD:CP_EIA-3528-21_Kemet-B | K4: =SUMIFS(Part_Suppliers!$E$2:$E$300,Part_Suppliers!$A$2:$A$300,$E4,Part_Suppliers!$H$2:$H$300,"Ja") -> 0.29 | L4: =F4*K4 -> 0.29 | M4: =IFERROR(VLOOKUP($E4,Parts!$A$2:$M$200,12,FALSE()),"") -> Polarisiert; Bauform B
A5: ENK-00001 | B5: 0.2 | C5: 40 | D5: C4 | E5: ENP-00006 | F5: 1 | G5: Bestücken | H5: KiCad | I5: =IFERROR(VLOOKUP(E5,Parts!$A$2:$S$200,4,FALSE()),"") -> 100 nF, 10 %, X7R, 100 V | J5: =IFERROR(VLOOKUP(E5,Parts!$A$2:$S$200,5,FALSE()),"") -> Capacitor_SMD:C_1206_3216Metric_Pad1.33x1.80mm_HandSolder | K5: =SUMIFS(Part_Suppliers!$E$2:$E$300,Part_Suppliers!$A$2:$A$300,$E5,Part_Suppliers!$H$2:$H$300,"Ja") -> 0.24 | L5: =F5*K5 -> 0.24 | M5: =IFERROR(VLOOKUP($E5,Parts!$A$2:$M$200,12,FALSE()),"") -> Spannungsfestigkeit, Dielektrikum und Bauform vor Bestellung gegen Schaltplan und Footprint prüfen; C1 ist in allen vier aktuellen Empty-Schemata derzeit DNP; C1 ist im aktuellen DuoRelay-Schema derzeit DNP
A6: ENK-00001 | B6: 0.2 | C6: 50 | D6: C5 | E6: ENP-00006 | F6: 1 | G6: Bestücken | H6: KiCad | I6: =IFERROR(VLOOKUP(E6,Parts!$A$2:$S$200,4,FALSE()),"") -> 100 nF, 10 %, X7R, 100 V | J6: =IFERROR(VLOOKUP(E6,Parts!$A$2:$S$200,5,FALSE()),"") -> Capacitor_SMD:C_1206_3216Metric_Pad1.33x1.80mm_HandSolder | K6: =SUMIFS(Part_Suppliers!$E$2:$E$300,Part_Suppliers!$A$2:$A$300,$E6,Part_Suppliers!$H$2:$H$300,"Ja") -> 0.24 | L6: =F6*K6 -> 0.24 | M6: =IFERROR(VLOOKUP($E6,Parts!$A$2:$M$200,12,FALSE()),"") -> Spannungsfestigkeit, Dielektrikum und Bauform vor Bestellung gegen Schaltplan und Footprint prüfen; C1 ist in allen vier aktuellen Empty-Schemata derzeit DNP; C1 ist im aktuellen DuoRelay-Schema derzeit DNP
A7: ENK-00001 | B7: 0.2 | C7: 60 | D7: C6 | E7: ENP-00056 | F7: 1 | G7: Bestücken | H7: KiCad | I7: =IFERROR(VLOOKUP(E7,Parts!$A$2:$S$200,4,FALSE()),"") -> 10 µF, ±20 %, 25 V, 85 °C, 2000 h | J7: =IFERROR(VLOOKUP(E7,Parts!$A$2:$S$200,5,FALSE()),"") -> Capacitor_SMD:CP_Elec_5x5.4 | K7: =SUMIFS(Part_Suppliers!$E$2:$E$300,Part_Suppliers!$A$2:$A$300,$E7,Part_Suppliers!$H$2:$H$300,"Ja") -> 0.18 | L7: =F7*K7 -> 0.18 | M7: =IFERROR(VLOOKUP($E7,Parts!$A$2:$M$200,12,FALSE()),"") -> Panasonic SMD-Aluminium-Elektrolytkondensator, 10 µF ±20 %, 25 V, 85 °C, 2000 h. Abmessungen Ø 5,0 × 5,4 mm passen exakt zum zugewiesenen KiCad-Footprint. C6 liegt zwischen +3V3_SYS und GND; 25 V bieten deutliche Spannungsreserve. Polarität beachten.
A8: ENK-00001 | B8: 0.2 | C8: 70 | D8: D1 | E8: ENP-00055 | F8: 1 | G8: Bestücken | H8: KiCad | I8: =IFERROR(VLOOKUP(E8,Parts!$A$2:$S$200,4,FALSE()),"") -> SS14, 1 A, 40 V, UF max. 0,5 V, IFSM 40 A | J8: =IFERROR(VLOOKUP(E8,Parts!$A$2:$S$200,5,FALSE()),"") -> Diode_SMD:D_SMA | K8: =SUMIFS(Part_Suppliers!$E$2:$E$300,Part_Suppliers!$A$2:$A$300,$E8,Part_Suppliers!$H$2:$H$300,"Ja") -> 0.18 | L8: =F8*K8 -> 0.18 | M8: =IFERROR(VLOOKUP($E8,Parts!$A$2:$M$200,12,FALSE()),"") -> Vishay Schottky-Gleichrichter im DO-214AC-/SMA-Gehäuse, 40 V Sperrspannung, 1 A Dauerstrom, 40 A Stoßstrom und Temperaturbereich −65 bis +150 °C. D1 entkoppelt +3V3_EXT, D2 entkoppelt +3V3_DEVKIT; beide speisen mit der Kathode +3V3_SYS. Zwei Stück je EnvNode Mini Rev 0.2.
A9: ENK-00001 | B9: 0.2 | C9: 80 | D9: D2 | E9: ENP-00055 | F9: 1 | G9: Bestücken | H9: KiCad | I9: =IFERROR(VLOOKUP(E9,Parts!$A$2:$S$200,4,FALSE()),"") -> SS14, 1 A, 40 V, UF max. 0,5 V, IFSM 40 A | J9: =IFERROR(VLOOKUP(E9,Parts!$A$2:$S$200,5,FALSE()),"") -> Diode_SMD:D_SMA | K9: =SUMIFS(Part_Suppliers!$E$2:$E$300,Part_Suppliers!$A$2:$A$300,$E9,Part_Suppliers!$H$2:$H$300,"Ja") -> 0.18 | L9: =F9*K9 -> 0.18 | M9: =IFERROR(VLOOKUP($E9,Parts!$A$2:$M$200,12,FALSE()),"") -> Vishay Schottky-Gleichrichter im DO-214AC-/SMA-Gehäuse, 40 V Sperrspannung, 1 A Dauerstrom, 40 A Stoßstrom und Temperaturbereich −65 bis +150 °C. D1 entkoppelt +3V3_EXT, D2 entkoppelt +3V3_DEVKIT; beide speisen mit der Kathode +3V3_SYS. Zwei Stück je EnvNode Mini Rev 0.2.
A10: ENK-00001 | B10: 0.2 | C10: 90 | D10: J1 | E10: ENP-00012 | F10: 1 | G10: Bestücken | H10: KiCad | I10: =IFERROR(VLOOKUP(E10,Parts!$A$2:$S$200,4,FALSE()),"") -> JST-PH, 2-polig, 2,00 mm | J10: =IFERROR(VLOOKUP(E10,Parts!$A$2:$S$200,5,FALSE()),"") -> Connector_JST:JST_PH_B2B-PH-K_1x02_P2.00mm_Vertical | K10: =SUMIFS(Part_Suppliers!$E$2:$E$300,Part_Suppliers!$A$2:$A$300,$E10,Part_Suppliers!$H$2:$H$300,"Ja") -> 1.3 | L10: =F10*K10 -> 1.3 | M10: =IFERROR(VLOOKUP($E10,Parts!$A$2:$M$200,12,FALSE()),"") -> 0
A11: ENK-00001 | B11: 0.2 | C11: 100 | D11: J2 | E11: ENP-00054 | F11: 1 | G11: Bestücken | H11: KiCad | I11: =IFERROR(VLOOKUP(E11,Parts!$A$2:$S$200,4,FALSE()),"") -> 2x7, 2,54 mm, THT, vertikal, vergoldet, Bauhöhe 8,4 mm | J11: =IFERROR(VLOOKUP(E11,Parts!$A$2:$S$200,5,FALSE()),"") -> Connector_PinSocket_2.54mm:PinSocket_2x07_P2.54mm_Vertical | K11: =SUMIFS(Part_Suppliers!$E$2:$E$300,Part_Suppliers!$A$2:$A$300,$E11,Part_Suppliers!$H$2:$H$300,"Ja") -> 0.56 | L11: =F11*K11 -> 0.56 | M11: =IFERROR(VLOOKUP($E11,Parts!$A$2:$M$200,12,FALSE()),"") -> Würth WR-PHD Dual Socket Header, 14 Kontakte, 2,54 mm, THT, vergoldet, 3 A/250 V AC. Der generische KiCad-Footprint bildet Raster und THT-Anordnung ab; Gehäusekontur/Courtyard sind nicht herstellerspezifisch.
A12: ENK-00001 | B12: 0.2 | C12: 110 | D12: J3 | E12: ENP-00054 | F12: 1 | G12: Bestücken | H12: KiCad | I12: =IFERROR(VLOOKUP(E12,Parts!$A$2:$S$200,4,FALSE()),"") -> 2x7, 2,54 mm, THT, vertikal, vergoldet, Bauhöhe 8,4 mm | J12: =IFERROR(VLOOKUP(E12,Parts!$A$2:$S$200,5,FALSE()),"") -> Connector_PinSocket_2.54mm:PinSocket_2x07_P2.54mm_Vertical | K12: =SUMIFS(Part_Suppliers!$E$2:$E$300,Part_Suppliers!$A$2:$A$300,$E12,Part_Suppliers!$H$2:$H$300,"Ja") -> 0.56 | L12: =F12*K12 -> 0.56 | M12: =IFERROR(VLOOKUP($E12,Parts!$A$2:$M$200,12,FALSE()),"") -> Würth WR-PHD Dual Socket Header, 14 Kontakte, 2,54 mm, THT, vergoldet, 3 A/250 V AC. Der generische KiCad-Footprint bildet Raster und THT-Anordnung ab; Gehäusekontur/Courtyard sind nicht herstellerspezifisch.
A13: ENK-00001 | B13: 0.2 | C13: 120 | D13: J4 | E13: ENP-00026 | F13: 1 | G13: Bestücken | H13: KiCad | I13: =IFERROR(VLOOKUP(E13,Parts!$A$2:$S$200,4,FALSE()),"") -> 4-polig, 1,00 mm | J13: =IFERROR(VLOOKUP(E13,Parts!$A$2:$S$200,5,FALSE()),"") -> Connector_JST:JST_SH_SM04B-SRSS-TB_1x04-1MP_P1.00mm_Horizontal | K13: =SUMIFS(Part_Suppliers!$E$2:$E$300,Part_Suppliers!$A$2:$A$300,$E13,Part_Suppliers!$H$2:$H$300,"Ja") -> 0.58 | L13: =F13*K13 -> 0.58 | M13: =IFERROR(VLOOKUP($E13,Parts!$A$2:$M$200,12,FALSE()),"") -> MPN-Suffix und Verpackungsform festlegen; nicht mit Qwiic-Pigtail zusammenführen.
... A21: ENK-00001 | B21: 0.2 | C21: 200 | D21: U3 | E21: ENP-00009 | F21: 1 | G21: Bestücken | H21: KiCad | I21: =IFERROR(VLOOKUP(E21,Parts!$A$2:$S$200,4,FALSE()),"") -> 3,3 V, 1 A | J21: =IFERROR(VLOOKUP(E21,Parts!$A$2:$S$200,5,FALSE()),"") -> Package_TO_SOT_SMD:SOT-223-3_TabPin2 | K21: =SUMIFS(Part_Suppliers!$E$2:$E$300,Part_Suppliers!$A$2:$A$300,$E21,Part_Suppliers!$H$2:$H$300,"Ja") -> 1 | L21: =F21*K21 -> 1 | M21: =IFERROR(VLOOKUP($E21,Parts!$A$2:$M$200,12,FALSE()),"") -> Footprint und thermische Auslegung vor Bestückung prüfen
A22: ENK-00001 | B22: 0.2 | C22: 210 | E22: ENP-00057 | F22: 1 | G22: Bestücken | H22: PCB | I22: =IFERROR(VLOOKUP(E22,Parts!$A$2:$S$200,4,FALSE()),"") -> Revision 0.2 | J22: =IFERROR(VLOOKUP(E22,Parts!$A$2:$S$200,5,FALSE()),"") -> PCB: MainBoards/EnvNode Mini/EnvNode Mini.kicad_pcb | K22: =SUMIFS(Part_Suppliers!$E$2:$E$300,Part_Suppliers!$A$2:$A$300,$E22,Part_Suppliers!$H$2:$H$300,"Ja") -> 0 | L22: =F22*K22 -> 0 | M22: =IFERROR(VLOOKUP($E22,Parts!$A$2:$M$200,12,FALSE()),"") -> Aktueller KiCad-Stand; Fertiger und konkrete Fertigungsvariante festlegen.
A23: ENK-00001 | B23: 0.2 | C23: 220 | E23: ENP-00080 | F23: 1 | G23: Mechanical | H23: Assembly | I23: =IFERROR(VLOOKUP(E23,Parts!$A$2:$S$200,4,FALSE()),"") -> 2-polig, Buchsenkontakte, IP68 gesteckt, Lötanschluss, Hinterwandmontage | J23: =IFERROR(VLOOKUP(E23,Parts!$A$2:$S$200,5,FALSE()),"") -> WEIPU SP13 Gehäusebuchse, 2-polig | K23: =SUMIFS(Part_Suppliers!$E$2:$E$300,Part_Suppliers!$A$2:$A$300,$E23,Part_Suppliers!$H$2:$H$300,"Ja") -> 0 | L23: =F23*K23 -> 0 | M23: =IFERROR(VLOOKUP($E23,Parts!$A$2:$M$200,12,FALSE()),"") -> Passend zu Kabelstecker SP1310/P2-N (ENP-00081). 13 A / 250 V AC; Panel-Ausschnitt Ø13 mm. Einsatz und Pinbelegung im Kit festlegen.
A24: ENK-00001 | B24: 0.2 | C24: 230 | E24: ENP-00081 | F24: 1 | G24: Mechanical | H24: Assembly | I24: =IFERROR(VLOOKUP(E24,Parts!$A$2:$S$200,4,FALSE()),"") -> 2-polig, Stiftkontakte, IP68 gesteckt, Lötanschluss | J24: =IFERROR(VLOOKUP(E24,Parts!$A$2:$S$200,5,FALSE()),"") -> WEIPU SP13 Kabelstecker, 2-polig | K24: =SUMIFS(Part_Suppliers!$E$2:$E$300,Part_Suppliers!$A$2:$A$300,$E24,Part_Suppliers!$H$2:$H$300,"Ja") -> 0 | L24: =F24*K24 -> 0 | M24: =IFERROR(VLOOKUP($E24,Parts!$A$2:$M$200,12,FALSE()),"") -> Passend zu Gehäusebuchse SP1312/S2-N (ENP-00080). 13 A / 250 V AC. Standardvariante I für Kabel-Ø 4–6,5 mm; Variante II für 5–8 mm vor Bestellung prüfen.
A25: ENK-00001 | B25: 0.2 | C25: 240 | E25: ENP-00084 | F25: 1 | G25: Mechanical | H25: Assembly | I25: =IFERROR(VLOOKUP(E25,Parts!$A$2:$S$200,4,FALSE()),"") -> 4-polig, Buchsenkontakte, IP68 gesteckt, Lötanschluss, Hinterwandmontage | J25: =IFERROR(VLOOKUP(E25,Parts!$A$2:$S$200,5,FALSE()),"") -> WEIPU SP13 Gehäusebuchse, 4-polig | K25: =SUMIFS(Part_Suppliers!$E$2:$E$300,Part_Suppliers!$A$2:$A$300,$E25,Part_Suppliers!$H$2:$H$300,"Ja") -> 0 | L25: =F25*K25 -> 0 | M25: =IFERROR(VLOOKUP($E25,Parts!$A$2:$M$200,12,FALSE()),"") -> Passend zu Kabelstecker SP1310/P4-N (ENP-00085). 5 A / 200 V AC; Panel-Ausschnitt Ø13 mm. Vorgesehen für I2C/GPIO/Sensorik.
A26: ENK-00001 | B26: 0.2 | C26: 250 | E26: ENP-00085 | F26: 1 | G26: Mechanical | H26: Assembly | I26: =IFERROR(VLOOKUP(E26,Parts!$A$2:$S$200,4,FALSE()),"") -> 4-polig, Stiftkontakte, IP68 gesteckt, Lötanschluss | J26: =IFERROR(VLOOKUP(E26,Parts!$A$2:$S$200,5,FALSE()),"") -> WEIPU SP13 Kabelstecker, 4-polig | K26: =SUMIFS(Part_Suppliers!$E$2:$E$300,Part_Suppliers!$A$2:$A$300,$E26,Part_Suppliers!$H$2:$H$300,"Ja") -> 0 | L26: =F26*K26 -> 0 | M26: =IFERROR(VLOOKUP($E26,Parts!$A$2:$M$200,12,FALSE()),"") -> Passend zu Gehäusebuchse SP1312/S4-N (ENP-00084). 5 A / 200 V AC. Standardvariante I für Kabel-Ø 4–6,5 mm; Variante II für 5–8 mm vor Bestellung prüfen.
A27: ENK-00001 | B27: 0.2 | C27: 260 | E27: ENP-00088 | F27: 1 | G27: Mechanical | H27: Assembly | I27: =IFERROR(VLOOKUP(E27,Parts!$A$2:$S$200,4,FALSE()),"") -> 5,5 × 2,1 mm, 2-polig, 20 V DC / 10 A, Lötanschluss | J27: =IFERROR(VLOOKUP(E27,Parts!$A$2:$S$200,5,FALSE()),"") -> 0 | K27: =SUMIFS(Part_Suppliers!$E$2:$E$300,Part_Suppliers!$A$2:$A$300,$E27,Part_Suppliers!$H$2:$H$300,"Ja") -> 5.75 | L27: =F27*K27 -> 5.75 | M27: =IFERROR(VLOOKUP($E27,Parts!$A$2:$M$200,12,FALSE()),"") -> Für 5-V-Versorgung in trockener Umgebung. Passend für DC-Stecker 5,5/2,1 mm mit 9,5 oder 12 mm Stiftlänge. Polarität im Kit verbindlich festlegen, empfohlen: Plus am Innenkontakt.
A28: ENK-00001 | B28: 0.2 | C28: 270 | D28: J6 | E28: ENP-00089 | F28: 1 | G28: Bestücken | H28: KiCad | I28: =IFERROR(VLOOKUP(E28,Parts!$A$2:$S$200,4,FALSE()),"") -> USB Type-C Receptacle, 16 Signalpins (+ 8 Dummy), 5 A, 48 V DC, SMD/TH, horizontal | J28: =IFERROR(VLOOKUP(E28,Parts!$A$2:$S$200,5,FALSE()),"") -> Connector_USB:USB_C_Receptacle_GCT_USB4105-xx-A_16P_TopMnt_Horizontal | K28: =SUMIFS(Part_Suppliers!$E$2:$E$300,Part_Suppliers!$A$2:$A$300,$E28,Part_Suppliers!$H$2:$H$300,"Ja") -> 0 | L28: =F28*K28 -> 0 | M28: =IFERROR(VLOOKUP($E28,Parts!$A$2:$M$200,12,FALSE()),"") -> Power-only mit Symbol Connector:USB_C_Receptacle_USB2.0_16P. Robuste Top-Mount-Ausführung mit vier durchkontaktierten Shield-/Haltezungen. D+/D− und SBU1/SBU2 NC; Shield an GND; CC1 und CC2 jeweils separat über 5,1 kΩ nach GND.
A29: ENK-00001 | B29: 0.2 | C29: 280 | D29: R5,R6 | E29: ENP-00090 | F29: 2 | G29: Bestücken | H29: KiCad | I29: =IFERROR(VLOOKUP(E29,Parts!$A$2:$S$200,4,FALSE()),"") -> 5,1 kΩ, 1 %, 250 mW | J29: =IFERROR(VLOOKUP(E29,Parts!$A$2:$S$200,5,FALSE()),"") -> Resistor_SMD:R_1206_3216Metric_Pad1.30x1.75mm_HandSolder | K29: =SUMIFS(Part_Suppliers!$E$2:$E$300,Part_Suppliers!$A$2:$A$300,$E29,Part_Suppliers!$H$2:$H$300,"Ja") -> 0.09 | L29: =F29*K29 -> 0.18 | M29: =IFERROR(VLOOKUP($E29,Parts!$A$2:$M$200,12,FALSE()),"") -> Zwei Stück als getrennte Rd-Widerstände: je einer von CC1 bzw. CC2 nach GND; CC1 und CC2 nicht miteinander verbinden.
A30: ENK-00002 | B30: 0.2 | C30: 10 | D30: C1 | E30: ENP-00006 | F30: 1 | G30: DNP | H30: KiCad | I30: =IFERROR(VLOOKUP(E30,Parts!$A$2:$S$200,4,FALSE()),"") -> 100 nF, 10 %, X7R, 100 V | J30: =IFERROR(VLOOKUP(E30,Parts!$A$2:$S$200,5,FALSE()),"") -> Capacitor_SMD:C_1206_3216Metric_Pad1.33x1.80mm_HandSolder | K30: =SUMIFS(Part_Suppliers!$E$2:$E$300,Part_Suppliers!$A$2:$A$300,$E30,Part_Suppliers!$H$2:$H$300,"Ja") -> 0.24 | L30: =F30*K30 -> 0.24 | M30: =IFERROR(VLOOKUP($E30,Parts!$A$2:$M$200,12,FALSE()),"") -> Spannungsfestigkeit, Dielektrikum und Bauform vor Bestellung gegen Schaltplan und Footprint prüfen; C1 ist in allen vier aktuellen Empty-Schemata derzeit DNP; C1 ist im aktuellen DuoRelay-Schema derzeit DNP
A31: ENK-00002 | B31: 0.2 | C31: 20 | D31: D1 | E31: ENP-00033 | F31: 1 | G31: Bestücken | H31: KiCad | I31: =IFERROR(VLOOKUP(E31,Parts!$A$2:$S$200,4,FALSE()),"") -> 1N4148W | J31: =IFERROR(VLOOKUP(E31,Parts!$A$2:$S$200,5,FALSE()),"") -> Diode_SMD:D_SOD-123 | K31: =SUMIFS(Part_Suppliers!$E$2:$E$300,Part_Suppliers!$A$2:$A$300,$E31,Part_Suppliers!$H$2:$H$300,"Ja") -> 0.02 | L31: =F31*K31 -> 0.02 | M31: =IFERROR(VLOOKUP($E31,Parts!$A$2:$M$200,12,FALSE()),"") -> 0
A32: ENK-00002 | B32: 0.2 | C32: 30 | D32: D2 | E32: ENP-00033 | F32: 1 | G32: Bestücken | H32: KiCad | I32: =IFERROR(VLOOKUP(E32,Parts!$A$2:$S$200,4,FALSE()),"") -> 1N4148W | J32: =IFERROR(VLOOKUP(E32,Parts!$A$2:$S$200,5,FALSE()),"") -> Diode_SMD:D_SOD-123 | K32: =SUMIFS(Part_Suppliers!$E$2:$E$300,Part_Suppliers!$A$2:$A$300,$E32,Part_Suppliers!$H$2:$H$300,"Ja") -> 0.02 | L32: =F32*K32 -> 0.02 | M32: =IFERROR(VLOOKUP($E32,Parts!$A$2:$M$200,12,FALSE()),"") -> 0
A33: ENK-00002 | B33: 0.2 | C33: 40 | D33: D3 | E33: ENP-00064 | F33: 1 | G33: Bestücken | H33: KiCad | I33: =IFERROR(VLOOKUP(E33,Parts!$A$2:$S$200,4,FALSE()),"") -> Hyperrot, 645 nm, 250 mcd, 140°, Vf 2,0–2,5 V, IF max. 30 mA | J33: =IFERROR(VLOOKUP(E33,Parts!$A$2:$S$200,5,FALSE()),"") -> LED_SMD:LED_1206_3216Metric_Pad1.42x1.75mm_HandSolder | K33: =SUMIFS(Part_Suppliers!$E$2:$E$300,Part_Suppliers!$A$2:$A$300,$E33,Part_Suppliers!$H$2:$H$300,"Ja") -> 0.11 | L33: =F33*K33 -> 0.11 | M33: =IFERROR(VLOOKUP($E33,Parts!$A$2:$M$200,12,FALSE()),"") -> Kingbright SMD-LED im 1206-/3216-Gehäuse, hyperrot, 250 mcd, 140° Abstrahlwinkel, Bauhöhe 1,1 mm. Im DuoRelay liegen D3/D4 über je 1,5 kΩ an +5 V; bei etwa 2 V Vorwärtsspannung fließen rund 2 mA.
A34: ENK-00002 | B34: 0.2 | C34: 50 | D34: D4 | E34: ENP-00064 | F34: 1 | G34: Bestücken | H34: KiCad | I34: =IFERROR(VLOOKUP(E34,Parts!$A$2:$S$200,4,FALSE()),"") -> Hyperrot, 645 nm, 250 mcd, 140°, Vf 2,0–2,5 V, IF max. 30 mA | J34: =IFERROR(VLOOKUP(E34,Parts!$A$2:$S$200,5,FALSE()),"") -> LED_SMD:LED_1206_3216Metric_Pad1.42x1.75mm_HandSolder | K34: =SUMIFS(Part_Suppliers!$E$2:$E$300,Part_Suppliers!$A$2:$A$300,$E34,Part_Suppliers!$H$2:$H$300,"Ja") -> 0.11 | L34: =F34*K34 -> 0.11 | M34: =IFERROR(VLOOKUP($E34,Parts!$A$2:$M$200,12,FALSE()),"") -> Kingbright SMD-LED im 1206-/3216-Gehäuse, hyperrot, 250 mcd, 140° Abstrahlwinkel, Bauhöhe 1,1 mm. Im DuoRelay liegen D3/D4 über je 1,5 kΩ an +5 V; bei etwa 2 V Vorwärtsspannung fließen rund 2 mA.
A35: ENK-00002 | B35: 0.2 | C35: 60 | D35: J1 | E35: ENP-00059 | F35: 1 | G35: Bestücken | H35: KiCad | I35: =IFERROR(VLOOKUP(E35,Parts!$A$2:$S$200,4,FALSE()),"") -> 2x7, 2,54 mm, THT, vertikal, vergoldet, 6,1 mm Stecklänge, 3,0 mm Lötstift | J35: =IFERROR(VLOOKUP(E35,Parts!$A$2:$S$200,5,FALSE()),"") -> EnvNode-Footprints:PinHeader_2x07_P2.54mm_Vertical_Bottom | K35: =SUMIFS(Part_Suppliers!$E$2:$E$300,Part_Suppliers!$A$2:$A$300,$E35,Part_Suppliers!$H$2:$H$300,"Ja") -> 0.3 | L35: =F35*K35 -> 0.3 | M35: =IFERROR(VLOOKUP($E35,Parts!$A$2:$M$200,12,FALSE()),"") -> Standard-THT-Stiftleiste mit 11,6 mm Gesamtlänge, vergoldeten Kontakten und 3 A Nennstrom. Die Bestückung von der Modulunterseite und die dafür passende Pinorientierung werden durch den Projekt-Footprint PinHeader_2x07_P2.54mm_Vertical_Bottom festgelegt. Einzelpreis inkl. MwSt., Stand 2026-09-01; Preis und Verfügbarkeit vor Bestellung prüfen.
A36: ENK-00002 | B36: 0.2 | C36: 70 | D36: J3 | E36: ENP-00034 | F36: 1 | G36: Bestücken | H36: KiCad | I36: =IFERROR(VLOOKUP(E36,Parts!$A$2:$S$200,4,FALSE()),"") -> 3-polig, 5,08 mm | J36: =IFERROR(VLOOKUP(E36,Parts!$A$2:$S$200,5,FALSE()),"") -> TerminalBlock_Phoenix:TerminalBlock_Phoenix_MKDS-3-3-5.08_1x03_P5.08mm_Horizontal | K36: =SUMIFS(Part_Suppliers!$E$2:$E$300,Part_Suppliers!$A$2:$A$300,$E36,Part_Suppliers!$H$2:$H$300,"Ja") -> 0 | L36: =F36*K36 -> 0 | M36: =IFERROR(VLOOKUP($E36,Parts!$A$2:$M$200,12,FALSE()),"") -> Exakte Hersteller-MPN ergänzen.
A37: ENK-00002 | B37: 0.2 | C37: 80 | D37: J4 | E37: ENP-00034 | F37: 1 | G37: Bestücken | H37: KiCad | I37: =IFERROR(VLOOKUP(E37,Parts!$A$2:$S$200,4,FALSE()),"") -> 3-polig, 5,08 mm | J37: =IFERROR(VLOOKUP(E37,Parts!$A$2:$S$200,5,FALSE()),"") -> TerminalBlock_Phoenix:TerminalBlock_Phoenix_MKDS-3-3-5.08_1x03_P5.08mm_Horizontal | K37: =SUMIFS(Part_Suppliers!$E$2:$E$300,Part_Suppliers!$A$2:$A$300,$E37,Part_Suppliers!$H$2:$H$300,"Ja") -> 0 | L37: =F37*K37 -> 0 | M37: =IFERROR(VLOOKUP($E37,Parts!$A$2:$M$200,12,FALSE()),"") -> Exakte Hersteller-MPN ergänzen.
A38: ENK-00002 | B38: 0.2 | C38: 90 | D38: K1 | E38: ENP-00023 | F38: 1 | G38: Bestücken | H38: KiCad | I38: =IFERROR(VLOOKUP(E38,Parts!$A$2:$S$200,4,FALSE()),"") -> 5 V, 1 Wechsler, 6 A | J38: =IFERROR(VLOOKUP(E38,Parts!$A$2:$S$200,5,FALSE()),"") -> Relay_THT:Relay_SPDT_Finder_34.51_Vertical | K38: =SUMIFS(Part_Suppliers!$E$2:$E$300,Part_Suppliers!$A$2:$A$300,$E38,Part_Suppliers!$H$2:$H$300,"Ja") -> 5.8 | L38: =F38*K38 -> 5.8 | M38: =IFERROR(VLOOKUP($E38,Parts!$A$2:$M$200,12,FALSE()),"") -> 0
A39: ENK-00002 | B39: 0.2 | C39: 100 | D39: K2 | E39: ENP-00023 | F39: 1 | G39: Bestücken | H39: KiCad | I39: =IFERROR(VLOOKUP(E39,Parts!$A$2:$S$200,4,FALSE()),"") -> 5 V, 1 Wechsler, 6 A | J39: =IFERROR(VLOOKUP(E39,Parts!$A$2:$S$200,5,FALSE()),"") -> Relay_THT:Relay_SPDT_Finder_34.51_Vertical | K39: =SUMIFS(Part_Suppliers!$E$2:$E$300,Part_Suppliers!$A$2:$A$300,$E39,Part_Suppliers!$H$2:$H$300,"Ja") -> 5.8 | L39: =F39*K39 -> 5.8 | M39: =IFERROR(VLOOKUP($E39,Parts!$A$2:$M$200,12,FALSE()),"") -> 0
... A48: ENK-00002 | B48: 0.2 | C48: 190 | D48: U1 | E48: ENP-00024 | F48: 1 | G48: DNP | H48: KiCad | I48: =IFERROR(VLOOKUP(E48,Parts!$A$2:$S$200,4,FALSE()),"") -> 2 Kbit, I²C, EUI-64, A0/A1, 1,7–5,5 V | J48: =IFERROR(VLOOKUP(E48,Parts!$A$2:$S$200,5,FALSE()),"") -> Package_TO_SOT_SMD:SOT-23-6 | K48: =SUMIFS(Part_Suppliers!$E$2:$E$300,Part_Suppliers!$A$2:$A$300,$E48,Part_Suppliers!$H$2:$H$300,"Ja") -> 0.32 | L48: =F48*K48 -> 0.32 | M48: =IFERROR(VLOOKUP($E48,Parts!$A$2:$M$200,12,FALSE()),"") -> Gemeinsamer Identifikations-EEPROM für alle Boards. Frühere Lieferantendaten gehörten zur falschen SPI-Version 25AA02E64T-I/OT und wurden entfernt; Bezugsquelle, Bestellnummer und Preis neu ergänzen. Auf Modulboards derzeit DNP.; In allen vier aktuellen Empty-Schemata derzeit DNP; A1 liegt an +3V3_SYS, A0 wird über J1 herausgeführt; U1 ist in den aktuellen DuoRelay- und AnalogHydroPressure-Schemata derzeit DNP Bezug als Cut Tape bei DigiKey; keine parametrischen Ersatztypen ohne vorprogrammierte EUI-64 verwenden.
A49: ENK-00002 | B49: 0.2 | C49: 200 | E49: ENP-00066 | F49: 1 | G49: Bestücken | H49: PCB | I49: =IFERROR(VLOOKUP(E49,Parts!$A$2:$S$200,4,FALSE()),"") -> Revision 0.2 | J49: =IFERROR(VLOOKUP(E49,Parts!$A$2:$S$200,5,FALSE()),"") -> PCB: Modules/FullSize/DuoRelay/DuoRelay.kicad_pcb | K49: =SUMIFS(Part_Suppliers!$E$2:$E$300,Part_Suppliers!$A$2:$A$300,$E49,Part_Suppliers!$H$2:$H$300,"Ja") -> 0 | L49: =F49*K49 -> 0 | M49: =IFERROR(VLOOKUP($E49,Parts!$A$2:$M$200,12,FALSE()),"") -> Aktueller KiCad-Stand; Fertiger und konkrete Fertigungsvariante festlegen.
A50: ENK-00003 | B50: 0.2 | C50: 10 | D50: C1 | E50: ENP-00006 | F50: 1 | G50: DNP | H50: KiCad | I50: =IFERROR(VLOOKUP(E50,Parts!$A$2:$S$200,4,FALSE()),"") -> 100 nF, 10 %, X7R, 100 V | J50: =IFERROR(VLOOKUP(E50,Parts!$A$2:$S$200,5,FALSE()),"") -> Capacitor_SMD:C_1206_3216Metric_Pad1.33x1.80mm_HandSolder | K50: =SUMIFS(Part_Suppliers!$E$2:$E$300,Part_Suppliers!$A$2:$A$300,$E50,Part_Suppliers!$H$2:$H$300,"Ja") -> 0.24 | L50: =F50*K50 -> 0.24 | M50: =IFERROR(VLOOKUP($E50,Parts!$A$2:$M$200,12,FALSE()),"") -> Spannungsfestigkeit, Dielektrikum und Bauform vor Bestellung gegen Schaltplan und Footprint prüfen; C1 ist in allen vier aktuellen Empty-Schemata derzeit DNP; C1 ist im aktuellen DuoRelay-Schema derzeit DNP
A51: ENK-00003 | B51: 0.2 | C51: 20 | D51: C3 | E51: ENP-00006 | F51: 1 | G51: Bestücken | H51: KiCad | I51: =IFERROR(VLOOKUP(E51,Parts!$A$2:$S$200,4,FALSE()),"") -> 100 nF, 10 %, X7R, 100 V | J51: =IFERROR(VLOOKUP(E51,Parts!$A$2:$S$200,5,FALSE()),"") -> Capacitor_SMD:C_1206_3216Metric_Pad1.33x1.80mm_HandSolder | K51: =SUMIFS(Part_Suppliers!$E$2:$E$300,Part_Suppliers!$A$2:$A$300,$E51,Part_Suppliers!$H$2:$H$300,"Ja") -> 0.24 | L51: =F51*K51 -> 0.24 | M51: =IFERROR(VLOOKUP($E51,Parts!$A$2:$M$200,12,FALSE()),"") -> Spannungsfestigkeit, Dielektrikum und Bauform vor Bestellung gegen Schaltplan und Footprint prüfen; C1 ist in allen vier aktuellen Empty-Schemata derzeit DNP; C1 ist im aktuellen DuoRelay-Schema derzeit DNP
A52: ENK-00003 | B52: 0.2 | C52: 30 | D52: C4 | E52: ENP-00028 | F52: 1 | G52: Bestücken | H52: KiCad | I52: =IFERROR(VLOOKUP(E52,Parts!$A$2:$S$200,4,FALSE()),"") -> 1 µF | J52: =IFERROR(VLOOKUP(E52,Parts!$A$2:$S$200,5,FALSE()),"") -> Capacitor_SMD:C_1206_3216Metric_Pad1.33x1.80mm_HandSolder | K52: =SUMIFS(Part_Suppliers!$E$2:$E$300,Part_Suppliers!$A$2:$A$300,$E52,Part_Suppliers!$H$2:$H$300,"Ja") -> 0.16 | L52: =F52*K52 -> 0.16 | M52: =IFERROR(VLOOKUP($E52,Parts!$A$2:$M$200,12,FALSE()),"") -> 0
A53: ENK-00003 | B53: 0.2 | C53: 40 | D53: C6 | E53: ENP-00067 | F53: 1 | G53: Bestücken | H53: KiCad | I53: =IFERROR(VLOOKUP(E53,Parts!$A$2:$S$200,4,FALSE()),"") -> 4,7 µF, 25 V, X7R, ±10 %, 1206 | J53: =IFERROR(VLOOKUP(E53,Parts!$A$2:$S$200,5,FALSE()),"") -> Capacitor_SMD:C_1206_3216Metric_Pad1.33x1.80mm_HandSolder | K53: =SUMIFS(Part_Suppliers!$E$2:$E$300,Part_Suppliers!$A$2:$A$300,$E53,Part_Suppliers!$H$2:$H$300,"Ja") -> 0.14 | L53: =F53*K53 -> 0.14 | M53: =IFERROR(VLOOKUP($E53,Parts!$A$2:$M$200,12,FALSE()),"") -> 25-V-Ausführung übertrifft die geforderten mindestens 10 V. Einzelpreis, Stand 2026-09-01; Preis und Verfügbarkeit vor Bestellung prüfen.
A54: ENK-00003 | B54: 0.2 | C54: 50 | D54: C7 | E54: ENP-00028 | F54: 1 | G54: Bestücken | H54: KiCad | I54: =IFERROR(VLOOKUP(E54,Parts!$A$2:$S$200,4,FALSE()),"") -> 1 µF | J54: =IFERROR(VLOOKUP(E54,Parts!$A$2:$S$200,5,FALSE()),"") -> Capacitor_SMD:C_1206_3216Metric_Pad1.33x1.80mm_HandSolder | K54: =SUMIFS(Part_Suppliers!$E$2:$E$300,Part_Suppliers!$A$2:$A$300,$E54,Part_Suppliers!$H$2:$H$300,"Ja") -> 0.16 | L54: =F54*K54 -> 0.16 | M54: =IFERROR(VLOOKUP($E54,Parts!$A$2:$M$200,12,FALSE()),"") -> 0
A55: ENK-00003 | B55: 0.2 | C55: 60 | D55: C8 | E55: ENP-00006 | F55: 1 | G55: Bestücken | H55: KiCad | I55: =IFERROR(VLOOKUP(E55,Parts!$A$2:$S$200,4,FALSE()),"") -> 100 nF, 10 %, X7R, 100 V | J55: =IFERROR(VLOOKUP(E55,Parts!$A$2:$S$200,5,FALSE()),"") -> Capacitor_SMD:C_1206_3216Metric_Pad1.33x1.80mm_HandSolder | K55: =SUMIFS(Part_Suppliers!$E$2:$E$300,Part_Suppliers!$A$2:$A$300,$E55,Part_Suppliers!$H$2:$H$300,"Ja") -> 0.24 | L55: =F55*K55 -> 0.24 | M55: =IFERROR(VLOOKUP($E55,Parts!$A$2:$M$200,12,FALSE()),"") -> Spannungsfestigkeit, Dielektrikum und Bauform vor Bestellung gegen Schaltplan und Footprint prüfen; C1 ist in allen vier aktuellen Empty-Schemata derzeit DNP; C1 ist im aktuellen DuoRelay-Schema derzeit DNP
...

Sheet Order_List
A1: Bestellliste für EnvNode-Bausätze
A2: Stückzahlen wählen; die Liste aggregiert gleiche Parts über alle Kits. DNP ist standardmäßig ausgeschlossen.
A4: Kit_ID | B4: Bausatz | C4: Stückzahl | E4: Option | F4: Auswahl
A5: ENK-00001 | B5: EnvNode Mini Bausatz | C5: 1 | E5: Optional bestellen | F5: Nein
A6: ENK-00002 | B6: DuoRelay FullSize Bausatz | C6: 0 | E6: DNP bestellen | F6: Ja
A7: ENK-00003 | B7: AnalogHydroPressure FullSize Bausatz | C7: 0
A8: ENK-00004 | B8: RainDetector Bausatz | C8: 0 | E8: Hinweis | F8: Bestellmenge wird bei hinterlegter Verpackungseinheit auf das nächste Vielfache aufgerundet.
A13: Part_ID | B13: Description | C13: Supplier | D13: Supplier_PN | E13: Bedarf | F13: Packaging_Unit | G13: Bedarf_gerundet | H13: Unit_Price_EUR | I13: Bedarfswert_EUR | J13: Import_Status | K13: URL | L13: Bestand | M13: Bestellt | N13: Deckung | O13: Bestellvorschlag | P13: Bestellmenge
A14: ENP-00003 | B14: =IFERROR(VLOOKUP($A14,Parts!$A$2:$M$200,3,FALSE()),"") -> PinSocket 1x4, 2.54 mm | C14: =IFERROR(VLOOKUP($A14,Stock!$A$5:$I$200,8,FALSE()),"") -> Reichelt | D14: =IFERROR(VLOOKUP($A14,Stock!$A$5:$I$200,9,FALSE()),"") -> BKL 10120946 | E14: =SUMIFS(Kit_BOM!$F$2:$F$204,Kit_BOM!$E$2:$E$204,$A14,Kit_BOM!$A$2:$A$204,$A$5,Kit_BOM!$G$2:$G$204,"Bestücken")*$C$5+SUMIFS(Kit_BOM!$F$2:$F$204,Kit_BOM!$E$2:$E$204,$A14,Kit_BOM!$A$2:$A$204,$A$5,Kit_BOM!$G$2:$G$204,"Mechanical")*$C$5+IF($F$5="Ja",SUMIFS(Kit_BOM!$F$2:$F$204,Kit_BOM!$E$2:$E$204,$A14,Kit_BOM!$A$2:$A$204,$A$5,Kit_BOM!$G$2:$G$204,"Optional")*$C$5,0)+IF($F$6="Ja",SUMIFS(Kit_BOM!$F$2:$F$204,Kit_BOM!$E$2:$E$204,$A14,Kit_BOM!$A$2:$A$204,$A$5,Kit_BOM!$G$2:$G$204,"DNP")*$C$5,0)+SUMIFS(Kit_BOM!$F$2:$F$204,Kit_BOM!$E$2:$E$204,$A14,Kit_BOM!$A$2:$A$204,$A$6,Kit_BOM!$G$2:$G$204,"Bestücken")*$C$6+SUMIFS(Kit_BOM!$F$2:$F$204,Kit_BOM!$E$2:$E$204,$A14,Kit_BOM!$A$2:$A$204,$A$6,Kit_BOM!$G$2:$G$204,"Mechanical")*$C$6+IF($F$5="Ja",SUMIFS(Kit_BOM!$F$2:$F$204,Kit_BOM!$E$2:$E$204,$A14,Kit_BOM!$A$2:$A$204,$A$6,Kit_BOM!$G$2:$G$204,"Optional")*$C$6,0)+IF($F$6="Ja",SUMIFS(Kit_BOM!$F$2:$F$204,Kit_BOM!$E$2:$E$204,$A14,Kit_BOM!$A$2:$A$204,$A$6,Kit_BOM!$G$2:$G$204,"DNP")*$C$6,0)+SUMIFS(Kit_BOM!$F$2:$F$204,Kit_BOM!$E$2:$E$204,$A14,Kit_BOM!$A$2:$A$204,$A$7,Kit_BOM!$G$2:$G$204,"Bestücken")*$C$7+SUMIFS(Kit_BOM!$F$2:$F$204,Kit_BOM!$E$2:$E$204,$A14,Kit_BOM!$A$2:$A$204,$A$7,Kit_BOM!$G$2:$G$204,"Mechanical")*$C$7+IF($F$5="Ja",SUMIFS(Kit_BOM!$F$2:$F$204,Kit_BOM!$E$2:$E$204,$A14,Kit_BOM!$A$2:$A$204,$A$7,Kit_BOM!$G$2:$G$204,"Optional")*$C$7,0)+IF($F$6="Ja",SUMIFS(Kit_BOM!$F$2:$F$204,Kit_BOM!$E$2:$E$204,$A14,Kit_BOM!$A$2:$A$204,$A$7,Kit_BOM!$G$2:$G$204,"DNP")*$C$7,0)+SUMIFS(Kit_BOM!$F$2:$F$204,Kit_BOM!$E$2:$E$204,$A14,Kit_BOM!$A$2:$A$204,$A$8,Kit_BOM!$G$2:$G$204,"Bestücken")*$C$8+SUMIFS(Kit_BOM!$F$2:$F$204,Kit_BOM!$E$2:$E$204,$A14,Kit_BOM!$A$2:$A$204,$A$8,Kit_BOM!$G$2:$G$204,"Mechanical")*$C$8+IF($F$5="Ja",SUMIFS(Kit_BOM!$F$2:$F$204,Kit_BOM!$E$2:$E$204,$A14,Kit_BOM!$A$2:$A$204,$A$8,Kit_BOM!$G$2:$G$204,"Optional")*$C$8,0)+IF($F$6="Ja",SUMIFS(Kit_BOM!$F$2:$F$204,Kit_BOM!$E$2:$E$204,$A14,Kit_BOM!$A$2:$A$204,$A$8,Kit_BOM!$G$2:$G$204,"DNP")*$C$8,0) -> 0 | F14: =IFERROR(IF(INDEX(Part_Suppliers!$G$2:$G$300,MATCH($A14&"|"&$C14,Part_Suppliers!$K$2:$K$300,0))=0,"",INDEX(Part_Suppliers!$G$2:$G$300,MATCH($A14&"|"&$C14,Part_Suppliers!$K$2:$K$300,0))),"") | G14: =IF($E14=0,0,IF(OR($F14="",$F14=0),$E14,CEILING($E14,$F14))) -> 0 | H14: =SUMIFS(Part_Suppliers!$E$2:$E$300,Part_Suppliers!$A$2:$A$300,$A14,Part_Suppliers!$B$2:$B$300,$C14) -> 0.81 | I14: =$G14*$H14 -> 0 | J14: =IF($E14=0,"Nicht benötigt",IF(LOWER($C14)<>"reichelt","Anderer Lieferant",IF($D14="","Supplier-PN fehlt","Reichelt bereit"))) -> Nicht benötigt | K14: =IFERROR(IF(INDEX(Part_Suppliers!$D$2:$D$300,MATCH($A14&"|"&$C14,Part_Suppliers!$K$2:$K$300,0))=0,"",INDEX(Part_Suppliers!$D$2:$D$300,MATCH($A14&"|"&$C14,Part_Suppliers!$K$2:$K$300,0))),"") -> https://www.reichelt.de/de/de/shop/produkt/buchsenleiste_2_54mm_1x4_gerade-266671 | L14: =IFERROR(VLOOKUP($A14,Stock!$A$5:$K$200,10,FALSE()),0) -> 4 | M14: =IFERROR(VLOOKUP($A14,Stock!$A$5:$K$200,11,FALSE()),0) -> 0 | N14: =$L14+$M14-$E14 -> 4 | O14: =IF($N14>=0,0,IF(OR($F14="",$F14=0),-$N14,CEILING(-$N14,$F14))) -> 0 | P14: 0
A15: ENP-00005 | B15: =IFERROR(VLOOKUP($A15,Parts!$A$2:$M$200,3,FALSE()),"") -> 4.7 kOhm 1% SMD 1206 | C15: =IFERROR(VLOOKUP($A15,Stock!$A$5:$I$200,8,FALSE()),"") -> Reichelt | D15: =IFERROR(VLOOKUP($A15,Stock!$A$5:$I$200,9,FALSE()),"") -> VIS CRCW12064K7 | E15: =SUMIFS(Kit_BOM!$F$2:$F$204,Kit_BOM!$E$2:$E$204,$A15,Kit_BOM!$A$2:$A$204,$A$5,Kit_BOM!$G$2:$G$204,"Bestücken")*$C$5+SUMIFS(Kit_BOM!$F$2:$F$204,Kit_BOM!$E$2:$E$204,$A15,Kit_BOM!$A$2:$A$204,$A$5,Kit_BOM!$G$2:$G$204,"Mechanical")*$C$5+IF($F$5="Ja",SUMIFS(Kit_BOM!$F$2:$F$204,Kit_BOM!$E$2:$E$204,$A15,Kit_BOM!$A$2:$A$204,$A$5,Kit_BOM!$G$2:$G$204,"Optional")*$C$5,0)+IF($F$6="Ja",SUMIFS(Kit_BOM!$F$2:$F$204,Kit_BOM!$E$2:$E$204,$A15,Kit_BOM!$A$2:$A$204,$A$5,Kit_BOM!$G$2:$G$204,"DNP")*$C$5,0)+SUMIFS(Kit_BOM!$F$2:$F$204,Kit_BOM!$E$2:$E$204,$A15,Kit_BOM!$A$2:$A$204,$A$6,Kit_BOM!$G$2:$G$204,"Bestücken")*$C$6+SUMIFS(Kit_BOM!$F$2:$F$204,Kit_BOM!$E$2:$E$204,$A15,Kit_BOM!$A$2:$A$204,$A$6,Kit_BOM!$G$2:$G$204,"Mechanical")*$C$6+IF($F$5="Ja",SUMIFS(Kit_BOM!$F$2:$F$204,Kit_BOM!$E$2:$E$204,$A15,Kit_BOM!$A$2:$A$204,$A$6,Kit_BOM!$G$2:$G$204,"Optional")*$C$6,0)+IF($F$6="Ja",SUMIFS(Kit_BOM!$F$2:$F$204,Kit_BOM!$E$2:$E$204,$A15,Kit_BOM!$A$2:$A$204,$A$6,Kit_BOM!$G$2:$G$204,"DNP")*$C$6,0)+SUMIFS(Kit_BOM!$F$2:$F$204,Kit_BOM!$E$2:$E$204,$A15,Kit_BOM!$A$2:$A$204,$A$7,Kit_BOM!$G$2:$G$204,"Bestücken")*$C$7+SUMIFS(Kit_BOM!$F$2:$F$204,Kit_BOM!$E$2:$E$204,$A15,Kit_BOM!$A$2:$A$204,$A$7,Kit_BOM!$G$2:$G$204,"Mechanical")*$C$7+IF($F$5="Ja",SUMIFS(Kit_BOM!$F$2:$F$204,Kit_BOM!$E$2:$E$204,$A15,Kit_BOM!$A$2:$A$204,$A$7,Kit_BOM!$G$2:$G$204,"Optional")*$C$7,0)+IF($F$6="Ja",SUMIFS(Kit_BOM!$F$2:$F$204,Kit_BOM!$E$2:$E$204,$A15,Kit_BOM!$A$2:$A$204,$A$7,Kit_BOM!$G$2:$G$204,"DNP")*$C$7,0)+SUMIFS(Kit_BOM!$F$2:$F$204,Kit_BOM!$E$2:$E$204,$A15,Kit_BOM!$A$2:$A$204,$A$8,Kit_BOM!$G$2:$G$204,"Bestücken")*$C$8+SUMIFS(Kit_BOM!$F$2:$F$204,Kit_BOM!$E$2:$E$204,$A15,Kit_BOM!$A$2:$A$204,$A$8,Kit_BOM!$G$2:$G$204,"Mechanical")*$C$8+IF($F$5="Ja",SUMIFS(Kit_BOM!$F$2:$F$204,Kit_BOM!$E$2:$E$204,$A15,Kit_BOM!$A$2:$A$204,$A$8,Kit_BOM!$G$2:$G$204,"Optional")*$C$8,0)+IF($F$6="Ja",SUMIFS(Kit_BOM!$F$2:$F$204,Kit_BOM!$E$2:$E$204,$A15,Kit_BOM!$A$2:$A$204,$A$8,Kit_BOM!$G$2:$G$204,"DNP")*$C$8,0) -> 4 | F15: =IFERROR(IF(INDEX(Part_Suppliers!$G$2:$G$300,MATCH($A15&"|"&$C15,Part_Suppliers!$K$2:$K$300,0))=0,"",INDEX(Part_Suppliers!$G$2:$G$300,MATCH($A15&"|"&$C15,Part_Suppliers!$K$2:$K$300,0))),"") | G15: =IF($E15=0,0,IF(OR($F15="",$F15=0),$E15,CEILING($E15,$F15))) -> 4 | H15: =SUMIFS(Part_Suppliers!$E$2:$E$300,Part_Suppliers!$A$2:$A$300,$A15,Part_Suppliers!$B$2:$B$300,$C15) -> 0.15 | I15: =$G15*$H15 -> 0.6 | J15: =IF($E15=0,"Nicht benötigt",IF(LOWER($C15)<>"reichelt","Anderer Lieferant",IF($D15="","Supplier-PN fehlt","Reichelt bereit"))) -> Reichelt bereit | K15: =IFERROR(IF(INDEX(Part_Suppliers!$D$2:$D$300,MATCH($A15&"|"&$C15,Part_Suppliers!$K$2:$K$300,0))=0,"",INDEX(Part_Suppliers!$D$2:$D$300,MATCH($A15&"|"&$C15,Part_Suppliers!$K$2:$K$300,0))),"") -> https://www.reichelt.de/de/de/shop/produkt/smd-widerstand_1206_4_7_kohm_250_mw_1_-238119 | L15: =IFERROR(VLOOKUP($A15,Stock!$A$5:$K$200,10,FALSE()),0) -> 12 | M15: =IFERROR(VLOOKUP($A15,Stock!$A$5:$K$200,11,FALSE()),0) -> 0 | N15: =$L15+$M15-$E15 -> 8 | O15: =IF($N15>=0,0,IF(OR($F15="",$F15=0),-$N15,CEILING(-$N15,$F15))) -> 0 | P15: 0
A16: ENP-00006 | B16: =IFERROR(VLOOKUP($A16,Parts!$A$2:$M$200,3,FALSE()),"") -> 100 nF Keramik SMD | C16: =IFERROR(VLOOKUP($A16,Stock!$A$5:$I$200,8,FALSE()),"") -> Reichelt | D16: =IFERROR(VLOOKUP($A16,Stock!$A$5:$I$200,9,FALSE()),"") -> KEM X7R1206A100N | E16: =SUMIFS(Kit_BOM!$F$2:$F$204,Kit_BOM!$E$2:$E$204,$A16,Kit_BOM!$A$2:$A$204,$A$5,Kit_BOM!$G$2:$G$204,"Bestücken")*$C$5+SUMIFS(Kit_BOM!$F$2:$F$204,Kit_BOM!$E$2:$E$204,$A16,Kit_BOM!$A$2:$A$204,$A$5,Kit_BOM!$G$2:$G$204,"Mechanical")*$C$5+IF($F$5="Ja",SUMIFS(Kit_BOM!$F$2:$F$204,Kit_BOM!$E$2:$E$204,$A16,Kit_BOM!$A$2:$A$204,$A$5,Kit_BOM!$G$2:$G$204,"Optional")*$C$5,0)+IF($F$6="Ja",SUMIFS(Kit_BOM!$F$2:$F$204,Kit_BOM!$E$2:$E$204,$A16,Kit_BOM!$A$2:$A$204,$A$5,Kit_BOM!$G$2:$G$204,"DNP")*$C$5,0)+SUMIFS(Kit_BOM!$F$2:$F$204,Kit_BOM!$E$2:$E$204,$A16,Kit_BOM!$A$2:$A$204,$A$6,Kit_BOM!$G$2:$G$204,"Bestücken")*$C$6+SUMIFS(Kit_BOM!$F$2:$F$204,Kit_BOM!$E$2:$E$204,$A16,Kit_BOM!$A$2:$A$204,$A$6,Kit_BOM!$G$2:$G$204,"Mechanical")*$C$6+IF($F$5="Ja",SUMIFS(Kit_BOM!$F$2:$F$204,Kit_BOM!$E$2:$E$204,$A16,Kit_BOM!$A$2:$A$204,$A$6,Kit_BOM!$G$2:$G$204,"Optional")*$C$6,0)+IF($F$6="Ja",SUMIFS(Kit_BOM!$F$2:$F$204,Kit_BOM!$E$2:$E$204,$A16,Kit_BOM!$A$2:$A$204,$A$6,Kit_BOM!$G$2:$G$204,"DNP")*$C$6,0)+SUMIFS(Kit_BOM!$F$2:$F$204,Kit_BOM!$E$2:$E$204,$A16,Kit_BOM!$A$2:$A$204,$A$7,Kit_BOM!$G$2:$G$204,"Bestücken")*$C$7+SUMIFS(Kit_BOM!$F$2:$F$204,Kit_BOM!$E$2:$E$204,$A16,Kit_BOM!$A$2:$A$204,$A$7,Kit_BOM!$G$2:$G$204,"Mechanical")*$C$7+IF($F$5="Ja",SUMIFS(Kit_BOM!$F$2:$F$204,Kit_BOM!$E$2:$E$204,$A16,Kit_BOM!$A$2:$A$204,$A$7,Kit_BOM!$G$2:$G$204,"Optional")*$C$7,0)+IF($F$6="Ja",SUMIFS(Kit_BOM!$F$2:$F$204,Kit_BOM!$E$2:$E$204,$A16,Kit_BOM!$A$2:$A$204,$A$7,Kit_BOM!$G$2:$G$204,"DNP")*$C$7,0)+SUMIFS(Kit_BOM!$F$2:$F$204,Kit_BOM!$E$2:$E$204,$A16,Kit_BOM!$A$2:$A$204,$A$8,Kit_BOM!$G$2:$G$204,"Bestücken")*$C$8+SUMIFS(Kit_BOM!$F$2:$F$204,Kit_BOM!$E$2:$E$204,$A16,Kit_BOM!$A$2:$A$204,$A$8,Kit_BOM!$G$2:$G$204,"Mechanical")*$C$8+IF($F$5="Ja",SUMIFS(Kit_BOM!$F$2:$F$204,Kit_BOM!$E$2:$E$204,$A16,Kit_BOM!$A$2:$A$204,$A$8,Kit_BOM!$G$2:$G$204,"Optional")*$C$8,0)+IF($F$6="Ja",SUMIFS(Kit_BOM!$F$2:$F$204,Kit_BOM!$E$2:$E$204,$A16,Kit_BOM!$A$2:$A$204,$A$8,Kit_BOM!$G$2:$G$204,"DNP")*$C$8,0) -> 3 | F16: =IFERROR(IF(INDEX(Part_Suppliers!$G$2:$G$300,MATCH($A16&"|"&$C16,Part_Suppliers!$K$2:$K$300,0))=0,"",INDEX(Part_Suppliers!$G$2:$G$300,MATCH($A16&"|"&$C16,Part_Suppliers!$K$2:$K$300,0))),"") -> 10 | G16: =IF($E16=0,0,IF(OR($F16="",$F16=0),$E16,CEILING($E16,$F16))) -> 10 | H16: =SUMIFS(Part_Suppliers!$E$2:$E$300,Part_Suppliers!$A$2:$A$300,$A16,Part_Suppliers!$B$2:$B$300,$C16) -> 0.24 | I16: =$G16*$H16 -> 2.4 | J16: =IF($E16=0,"Nicht benötigt",IF(LOWER($C16)<>"reichelt","Anderer Lieferant",IF($D16="","Supplier-PN fehlt","Reichelt bereit"))) -> Reichelt bereit | K16: =IFERROR(IF(INDEX(Part_Suppliers!$D$2:$D$300,MATCH($A16&"|"&$C16,Part_Suppliers!$K$2:$K$300,0))=0,"",INDEX(Part_Suppliers!$D$2:$D$300,MATCH($A16&"|"&$C16,Part_Suppliers!$K$2:$K$300,0))),"") -> https://www.reichelt.de/de/de/shop/produkt/vielschicht_kerko_1206_100_nf_10_x7r_100_v_125_c-207151 | L16: =IFERROR(VLOOKUP($A16,Stock!$A$5:$K$200,10,FALSE()),0) -> 0 | M16: =IFERROR(VLOOKUP($A16,Stock!$A$5:$K$200,11,FALSE()),0) -> 10 | N16: =$L16+$M16-$E16 -> 7 | O16: =IF($N16>=0,0,IF(OR($F16="",$F16=0),-$N16,CEILING(-$N16,$F16))) -> 0 | P16: 0
A17: ENP-00007 | B17: =IFERROR(VLOOKUP($A17,Parts!$A$2:$M$200,3,FALSE()),"") -> 10 uF Keramik SMD | C17: =IFERROR(VLOOKUP($A17,Stock!$A$5:$I$200,8,FALSE()),"") -> Reichelt | D17: =IFERROR(VLOOKUP($A17,Stock!$A$5:$I$200,9,FALSE()),"") -> 12063C106KAT2A | E17: =SUMIFS(Kit_BOM!$F$2:$F$204,Kit_BOM!$E$2:$E$204,$A17,Kit_BOM!$A$2:$A$204,$A$5,Kit_BOM!$G$2:$G$204,"Bestücken")*$C$5+SUMIFS(Kit_BOM!$F$2:$F$204,Kit_BOM!$E$2:$E$204,$A17,Kit_BOM!$A$2:$A$204,$A$5,Kit_BOM!$G$2:$G$204,"Mechanical")*$C$5+IF($F$5="Ja",SUMIFS(Kit_BOM!$F$2:$F$204,Kit_BOM!$E$2:$E$204,$A17,Kit_BOM!$A$2:$A$204,$A$5,Kit_BOM!$G$2:$G$204,"Optional")*$C$5,0)+IF($F$6="Ja",SUMIFS(Kit_BOM!$F$2:$F$204,Kit_BOM!$E$2:$E$204,$A17,Kit_BOM!$A$2:$A$204,$A$5,Kit_BOM!$G$2:$G$204,"DNP")*$C$5,0)+SUMIFS(Kit_BOM!$F$2:$F$204,Kit_BOM!$E$2:$E$204,$A17,Kit_BOM!$A$2:$A$204,$A$6,Kit_BOM!$G$2:$G$204,"Bestücken")*$C$6+SUMIFS(Kit_BOM!$F$2:$F$204,Kit_BOM!$E$2:$E$204,$A17,Kit_BOM!$A$2:$A$204,$A$6,Kit_BOM!$G$2:$G$204,"Mechanical")*$C$6+IF($F$5="Ja",SUMIFS(Kit_BOM!$F$2:$F$204,Kit_BOM!$E$2:$E$204,$A17,Kit_BOM!$A$2:$A$204,$A$6,Kit_BOM!$G$2:$G$204,"Optional")*$C$6,0)+IF($F$6="Ja",SUMIFS(Kit_BOM!$F$2:$F$204,Kit_BOM!$E$2:$E$204,$A17,Kit_BOM!$A$2:$A$204,$A$6,Kit_BOM!$G$2:$G$204,"DNP")*$C$6,0)+SUMIFS(Kit_BOM!$F$2:$F$204,Kit_BOM!$E$2:$E$204,$A17,Kit_BOM!$A$2:$A$204,$A$7,Kit_BOM!$G$2:$G$204,"Bestücken")*$C$7+SUMIFS(Kit_BOM!$F$2:$F$204,Kit_BOM!$E$2:$E$204,$A17,Kit_BOM!$A$2:$A$204,$A$7,Kit_BOM!$G$2:$G$204,"Mechanical")*$C$7+IF($F$5="Ja",SUMIFS(Kit_BOM!$F$2:$F$204,Kit_BOM!$E$2:$E$204,$A17,Kit_BOM!$A$2:$A$204,$A$7,Kit_BOM!$G$2:$G$204,"Optional")*$C$7,0)+IF($F$6="Ja",SUMIFS(Kit_BOM!$F$2:$F$204,Kit_BOM!$E$2:$E$204,$A17,Kit_BOM!$A$2:$A$204,$A$7,Kit_BOM!$G$2:$G$204,"DNP")*$C$7,0)+SUMIFS(Kit_BOM!$F$2:$F$204,Kit_BOM!$E$2:$E$204,$A17,Kit_BOM!$A$2:$A$204,$A$8,Kit_BOM!$G$2:$G$204,"Bestücken")*$C$8+SUMIFS(Kit_BOM!$F$2:$F$204,Kit_BOM!$E$2:$E$204,$A17,Kit_BOM!$A$2:$A$204,$A$8,Kit_BOM!$G$2:$G$204,"Mechanical")*$C$8+IF($F$5="Ja",SUMIFS(Kit_BOM!$F$2:$F$204,Kit_BOM!$E$2:$E$204,$A17,Kit_BOM!$A$2:$A$204,$A$8,Kit_BOM!$G$2:$G$204,"Optional")*$C$8,0)+IF($F$6="Ja",SUMIFS(Kit_BOM!$F$2:$F$204,Kit_BOM!$E$2:$E$204,$A17,Kit_BOM!$A$2:$A$204,$A$8,Kit_BOM!$G$2:$G$204,"DNP")*$C$8,0) -> 1 | F17: =IFERROR(IF(INDEX(Part_Suppliers!$G$2:$G$300,MATCH($A17&"|"&$C17,Part_Suppliers!$K$2:$K$300,0))=0,"",INDEX(Part_Suppliers!$G$2:$G$300,MATCH($A17&"|"&$C17,Part_Suppliers!$K$2:$K$300,0))),"") -> 10 | G17: =IF($E17=0,0,IF(OR($F17="",$F17=0),$E17,CEILING($E17,$F17))) -> 10 | H17: =SUMIFS(Part_Suppliers!$E$2:$E$300,Part_Suppliers!$A$2:$A$300,$A17,Part_Suppliers!$B$2:$B$300,$C17) -> 0.11 | I17: =$G17*$H17 -> 1.1 | J17: =IF($E17=0,"Nicht benötigt",IF(LOWER($C17)<>"reichelt","Anderer Lieferant",IF($D17="","Supplier-PN fehlt","Reichelt bereit"))) -> Reichelt bereit | K17: =IFERROR(IF(INDEX(Part_Suppliers!$D$2:$D$300,MATCH($A17&"|"&$C17,Part_Suppliers!$K$2:$K$300,0))=0,"",INDEX(Part_Suppliers!$D$2:$D$300,MATCH($A17&"|"&$C17,Part_Suppliers!$K$2:$K$300,0))),"") -> https://www.reichelt.de/de/de/shop/produkt/mlcc_1206_10_f_25_v_-10_x7r-409262 | L17: =IFERROR(VLOOKUP($A17,Stock!$A$5:$K$200,10,FALSE()),0) -> 0 | M17: =IFERROR(VLOOKUP($A17,Stock!$A$5:$K$200,11,FALSE()),0) -> 10 | N17: =$L17+$M17-$E17 -> 9 | O17: =IF($N17>=0,0,IF(OR($F17="",$F17=0),-$N17,CEILING(-$N17,$F17))) -> 0 | P17: 0
