Workbook

Sheet Parts
A1: Part_ID | B1: Category | C1: Description | D1: Value_Rating | E1: Package_Footprint | F1: Manufacturer | G1: MPN | H1: Supplier | I1: Supplier_PN | J1: URL | K1: Unit_Price_EUR | L1: Purchase_Unit | M1: Packaging_Unit | N1: Found_In | O1: KiCad_References | P1: Source | Q1: Review_Status | R1: Notes | S1: Duplicate_Check_Key
A2: ENP-00001 | B2: Kabelsatz | C2: Set, SET JST-PH 4-polig 2.00mm vertikaler PCB-Stecker, Buchse THT | D2: JST-PH, 4-polig, Set | F2: JST | H2: eBay | J2: https://www.ebay.de/itm/175537690511?_skw=jst+ph+set&itmmeta=01M0AMR98NFGJV2FS30RR17BQ3&hash=item28dedc978f:g:A3kAAOSw229j0YAt&itmprp=enc%3AAQALAAAA0GfYFPkwiKCW4ZNSs2u11xAqJnJgTdJ%2FIJ1I2fxZKRMDiu6X0YrWY5D3w4DQOc5o%2FaOXGmcjIgTnzr6ZSr5vXhmBWytsd%2BVqmj0wzTE8DG%2BTs8RqbjdKpejAkG5A8BZqR0CHVQRoh5S5YInpcAcul6x8Wctn1VQHQBXPR%2FXsSs9oWck2%2BQ7koAWk9BEZEN9dagXH6v3Mmz5PHheo1V3%2ByPo1rz9Au%2BRLA4rvEIjR474lCC3Jyl3mD3occXmLZjl7i6IY9cBlKcCfkbIa4zkXYnk%3D%7Ctkp%3ABk9SR9aU4dSCaA | K2: 15.3 | L2: Stk | M2: 10 | N2: EnvNode | O2: GPIO's | P2: BOM_Mainboard.xlsx | Q2: OK | R2: GPIO-Anschlüsse; exakte Herstellerartikelnummer vor Bestellung gegen Footprint und Orientierung prüfen Set-Inhalt gegenüber dem separat aus KiCad abgeleiteten PCB-Header prüfen. | S2: =IF(G2<>"",UPPER(TRIM(G2)),UPPER(TRIM(C2&"|"&E2))) -> SET, SET JST-PH 4-POLIG 2.00MM VERTIKALER PCB-STECKER, BUCHSE THT|
A3: ENP-00002 | B3: Kabelsatz | C3: Qwiic/JST-SH, 4-poliges Pigtail JST | D3: JST-SH/Qwiic, 4-polig | F3: JST | H3: eBay | J3: https://www.ebay.de/itm/173373182853?var=472082388514&mkevt=1&mkcid=1&mkrid=707-53477-19255-0&campid=5338900900&toolid=20006&_ul=DE&customid=56357.a3ed6a6e290d515ebd3c2719dda804fc89ac0aba&gclid=Cj0KCQjwkOvTBhDgARIsAKUNyRushMKf0tSoocu00ZtebiM-JK-GbXhf7yKDhPSZVdsZL-EEyywLbIcaAndsEALw_wcB&gbraid=0AAAAAqbaHat7Q_3DRZ3ZEIWwp68U1IjOi&adtype=pla&loc_physical_ms=9041684 | K3: 6.69 | L3: Stk | M3: 10 | N3: EnvNode | O3: I2CA0 1-3 I2C1 1-3 | P3: BOM_Mainboard.xlsx | Q3: OK | R3: Qwiic-Konvention: GND=schwarz, 3V3=rot, SDA=blau, SCL=gelb; Kabelbelegung vor Anschluss prüfen Pigtail ist ein Beschaffungsartikel und nicht der PCB-Steckverbinder. | S3: =IF(G3<>"",UPPER(TRIM(G3)),UPPER(TRIM(C3&"|"&E3))) -> QWIIC/JST-SH, 4-POLIGES PIGTAIL JST|
A4: ENP-00003 | B4: Steckverbinder | C4: PinSocket 1x4, 2.54 mm | D4: 1x4, 2,54 mm | E4: PinSocket_1x04_P2.54mm_Vertical | F4: fischer Elektronik | G4: 10120946 | H4: reichelt | I4: BKL 10120946 | J4: https://www.reichelt.de/de/de/shop/produkt/buchsenleiste_2_54mm_1x4_gerade-266671 | K4: 0.81 | L4: Stk | N4: EnvNode; RainDetector | O4: EnvNode I2C0_4,I2C1_4; RainDetector J3,J4 | P4: BOM_Mainboard.xlsx | Q4: OK | R4: Für interne Qwiic-Breakouts; Bauhöhe und Ausführung passend zur Mechanik wählen | S4: =IF(G4<>"",UPPER(TRIM(G4)),UPPER(TRIM(C4&"|"&E4))) -> 10120946
A5: ENP-00004 | B5: Steckverbinder | C5: PinSocket 1x20, 2.54mm, cut to 19 Pins | D5: 1x20, 2,54 mm, trennbar | F5: fischer Elektronik | G5: BL1.20 G | H5: reichelt | I5: FIS BL1 20 G | J5: https://www.reichelt.de/de/de/shop/produkt/buchsenleiste_2_54mm_1x20_trennbar_vergoldet-283787 | K5: 2.55 | L5: Stk | N5: EnvNode | O5: ESP32 | P5: BOM_Mainboard.xlsx | Q5: OK | R5: Für ESP32-DevKitC mit 38 Pins; alternativ eine geeignete 38-Pin-ESP32-Fassung verwenden | S5: =IF(G5<>"",UPPER(TRIM(G5)),UPPER(TRIM(C5&"|"&E5))) -> BL1.20 G
A6: ENP-00005 | B6: Widerstand | C6: 4.7 kOhm 1% SMD 1206 | D6: 4,7 kΩ, 1 %, 250 mW | E6: Resistor_SMD:R_1206_3216Metric_Pad1.30x1.75mm_HandSolder | F6: Vishay | G6: CRCW12064K70FKEA | H6: reichelt | I6: VIS CRCW12064K7 | J6: https://www.reichelt.de/de/de/shop/produkt/smd-widerstand_1206_4_7_kohm_250_mw_1_-238119 | K6: 0.15 | L6: Stk | N6: EnvNode; EnvNodeMini Rev 0.2; AnalogInput Rev 0.1; AnalogHydroPressure | O6: EnvNode R1-R4; EnvNodeMini Rev 0.2 R1-R4; AnalogInput Rev 0.1 R2; AnalogHydroPressure R2 | P6: BOM_Mainboard.xlsx | Q6: OK | R6: I2C-Pull-ups für die beiden I2C-Busse | S6: =IF(G6<>"",UPPER(TRIM(G6)),UPPER(TRIM(C6&"|"&E6))) -> CRCW12064K70FKEA
A7: ENP-00006 | B7: Kondensator | C7: 100 nF Keramik SMD | D7: 100 nF, 10 %, X7R, 100 V | E7: Capacitor_SMD:C_1206_3216Metric_Pad1.33x1.80mm_HandSolder | F7: Kyocera | G7: C1206F104K1RACTU | H7: reichelt | I7: KEM X7R1206A100N | J7: https://www.reichelt.de/de/de/shop/produkt/vielschicht_kerko_1206_100_nf_10_x7r_100_v_125_c-207151 | K7: 0.24 | L7: Stk | M7: 10 | N7: EnvNode; EnvNodeMini Rev 0.2; AnalogHydroPressure; RainDetector; SolarRadiation; Empty FullSize/HalfSize SMD/THT; DuoRelay Rev 0.2 | O7: EnvNode C3,C4; EnvNodeMini Rev 0.2 C1,C4,C5; AnalogHydroPressure C1,C3,C8; RainDetector C1; SolarRadiation C1; Empty-Boards C1; DuoRelay Rev 0.2 C1 | P7: BOM_Mainboard.xlsx | Q7: OK | R7: Spannungsfestigkeit, Dielektrikum und Bauform vor Bestellung gegen Schaltplan und Footprint prüfen; C1 ist in allen vier aktuellen Empty-Schemata derzeit DNP; C1 ist im aktuellen DuoRelay-Schema derzeit DNP | S7: =IF(G7<>"",UPPER(TRIM(G7)),UPPER(TRIM(C7&"|"&E7))) -> C1206F104K1RACTU
A8: ENP-00007 | B8: Kondensator | C8: 10 uF Keramik SMD | D8: 10 µF, 25 V, X7R | E8: Capacitor_SMD:C_1206_3216Metric_Pad1.33x1.80mm_HandSolder | F8: Kyocera AVX | G8: 12063C106KAT2A | H8: reichelt | I8: 12063C106KAT2A | J8: https://www.reichelt.de/de/de/shop/produkt/mlcc_1206_10_f_25_v_-10_x7r-409262 | K8: 0.11 | L8: Stk | M8: 10 | N8: EnvNode; EnvNodeMini Rev 0.2 | O8: EnvNode C1; EnvNodeMini Rev 0.2 C2 | P8: BOM_Mainboard.xlsx | Q8: OK | R8: Spannungsfestigkeit, Dielektrikum und Bauform vor Bestellung gegen Schaltplan und Footprint prüfen | S8: =IF(G8<>"",UPPER(TRIM(G8)),UPPER(TRIM(C8&"|"&E8))) -> 12063C106KAT2A
A9: ENP-00008 | B9: Kondensator | C9: 47 uF 10V Tantal | D9: 47 µF, 10 V | E9: Capacitor_Tantalum_SMD:CP_EIA-3528-21_Kemet-B | F9: Kyocera AVX | G9: TAJB476K010RNJ | H9: reichelt | I9: TAJ 3528 47/10 | J9: https://www.reichelt.de/de/de/shop/produkt/smd-tantal_kondensator_47_f_10_v-167014 | K9: 0.29 | L9: Stk | N9: EnvNode; EnvNodeMini Rev 0.2 | O9: EnvNode C2; EnvNodeMini Rev 0.2 C3 | P9: BOM_Mainboard.xlsx | Q9: OK | R9: Polarisiert; Bauform B | S9: =IF(G9<>"",UPPER(TRIM(G9)),UPPER(TRIM(C9&"|"&E9))) -> TAJB476K010RNJ
A10: ENP-00009 | B10: Spannungsregler | C10: LDO 3.3V SOT-223 | D10: 3,3 V, 1 A | E10: Package_TO_SOT_SMD:SOT-223-3_TabPin2 | F10: Texas Instruments | G10: LM3940IMP-3.3/NOPB | H10: reichelt | I10: LM 3940 IMP-3 | J10: https://www.reichelt.de/de/de/shop/produkt/ldo-spannungsregler_fix_3_3_vout_1_a_sot-223-109407?search=LM3940%2520& | K10: 1 | L10: Stk | M10: 3 | N10: EnvNode; EnvNodeMini Rev 0.2 | O10: EnvNode U1; EnvNodeMini Rev 0.2 U3 | P10: BOM_Mainboard.xlsx | Q10: OK | R10: Footprint und thermische Auslegung vor Bestückung prüfen | S10: =IF(G10<>"",UPPER(TRIM(G10)),UPPER(TRIM(C10&"|"&E10))) -> LM3940IMP-3.3/NOPB
A11: ENP-00010 | B11: Entwicklungsmodul | C11: ESP32-DevKitC | D11: 38 Pin | E11: PCM_Espressif:ESP32-DevKitC | F11: Espressif Systems | K11: 5 | L11: Stk | M11: 3 | N11: EnvNode; EnvNodeMini Rev 0.2 | O11: EnvNode U2; EnvNodeMini Rev 0.2 U1 | P11: BOM_Mainboard.xlsx | Q11: OK | R11: Exakte Modulvariante und Pinout vor Bestückung prüfen Hersteller/MPN aus verschobenen Altdaten korrigiert; genaue DevKitC-Variante fehlt. | S11: =IF(G11<>"",UPPER(TRIM(G11)),UPPER(TRIM(C11&"|"&E11))) -> ESP32-DEVKITC|PCM_ESPRESSIF:ESP32-DEVKITC
A12: ENP-00011 | B12: PCB | C12: EnvNode Mainboard Rev 0.1 | D12: Revision 0.1 | F12: JLCPCB | H12: JLCPCB | J12: https://jlcpcb.com/file/download?uuid=eef69d2d694441c8ab71168d8447cb4c&businessType=example | K12: 7.85 | L12: Stk | N12: EnvNode | P12: BOM_Mainboard.xlsx | Q12: OK | R12: Unbestückte Leiterplatte; SMD-Lötjumper sind PCB-Strukturen und keine Kaufteile Historische PCB-Revision; aktueller KiCad-Stand ist Revision 0.2. | S12: =IF(G12<>"",UPPER(TRIM(G12)),UPPER(TRIM(C12&"|"&E12))) -> ENVNODE MAINBOARD REV 0.1|
A13: ENP-00012 | B13: Steckverbinder | C13: JST - Stiftleiste, gerade, 1x2-polig - PH | D13: JST-PH, 2-polig, 2,00 mm | E13: Connector_JST:JST_PH_B2B-PH-K_1x02_P2.00mm_Vertical | F13: JST | G13: B2B-PH-K-S | H13: reichelt | I13: JST PH2P ST | J13: https://www.reichelt.de/de/de/shop/produkt/jst_-_stiftleiste_gerade_1x2-polig_-_ph-185049 | K13: 1.3 | L13: Stk | N13: EnvNode; EnvNodeMini Rev 0.2 | O13: EnvNode J1; EnvNodeMini Rev 0.2 J1 | P13: BOM_Mainboard.xlsx | Q13: OK | S13: =IF(G13<>"",UPPER(TRIM(G13)),UPPER(TRIM(C13&"|"&E13))) -> B2B-PH-K-S
A14: ENP-00013 | B14: MOSFET | C14: MOSFET, N-Ch 30V 5,7A 0,018R, SOT-23 | D14: N-Kanal, 30 V, 5,7 A | E14: Package_TO_SOT_SMD:SOT-23 | F14: Alpha&Omega Semiconductor | G14: AO3400A | H14: reichelt | I14: AO3400A | J14: https://www.reichelt.de/de/de/shop/produkt/mosfet_n-ch_30v_5_7a_0_018r_sot-23-166490 | K14: 0.18 | L14: Stk | N14: RainDetector | O14: Q1 | P14: BOM_Mainboard.xlsx | Q14: OK | S14: =IF(G14<>"",UPPER(TRIM(G14)),UPPER(TRIM(C14&"|"&E14))) -> AO3400A
A15: ENP-00014 | B15: Sensormodul | C15: Arduino - Temperatur- & Feuchtigkeitssensor, SHTC3 | D15: SHTC3 Breakout | F15: Soldered | G15: 333032 | H15: reichelt | I15: DEBO SENS SHTC3 | J15: https://www.reichelt.de/de/de/shop/produkt/arduino_-_temperatur-_feuchtigkeitssensor_shtc3-375947 | K15: 5.3 | L15: Stk | N15: Sensor | P15: BOM_Mainboard.xlsx | Q15: OK | S15: =IF(G15<>"",UPPER(TRIM(G15)),UPPER(TRIM(C15&"|"&E15))) -> 333032
A16: ENP-00015 | B16: Entwicklungsmodul | C16: Entwicklerboards - ADC, 4 Kanal, 16-Bit, ADS1115 | D16: ADS1115 Breakout, 4 Kanal, 16 Bit | F16: Soldered | G16: 333095 | H16: reichelt | I16: DEBO ADC 16BIT | J16: https://www.reichelt.de/de/de/shop/produkt/entwicklerboards_-_adc_4_kanal_16-bit_ads1115-372499?search=ADS1115&#open-modal-image-big-slider | K16: 8.85 | L16: Stk | N16: A/D Wandler | P16: BOM_Mainboard.xlsx | Q16: OK | S16: =IF(G16<>"",UPPER(TRIM(G16)),UPPER(TRIM(C16&"|"&E16))) -> 333095
A17: ENP-00016 | B17: Widerstand | C17: SMD-Widerstand, 1206, 100 kOhm, 250 mW, 0,1% | D17: 100 kΩ, 0,1 %, 250 mW | E17: Resistor_SMD:R_1206_3216Metric_Pad1.30x1.75mm_HandSolder | F17: Panasonic | G17: ERA8AEB104V | H17: reichelt | I17: PAN ERA8AEB104V | J17: https://www.reichelt.de/de/de/shop/produkt/smd-widerstand_1206_100_kohm_250_mw_0_1_-238081 | K17: 0.83 | L17: Stk | N17: RainDetector; DuoRelay; AnalogHydroPressure | O17: RainDetector R2,R4; DuoRelay R3,R4; AnalogHydroPressure R7 | P17: BOM_Mainboard.xlsx | Q17: OK | R17: Lieferanten-Bestellnummer in der Altdatei enthält vermischte Angaben. | S17: =IF(G17<>"",UPPER(TRIM(G17)),UPPER(TRIM(C17&"|"&E17))) -> ERA8AEB104V
A18: ENP-00017 | B18: Widerstand | C18: SMD-Widerstand, 1206, 100 Ohm, 250 mW, 5% | D18: 100 Ω, 5 %, 250 mW | E18: Resistor_SMD:R_1206_3216Metric_Pad1.30x1.75mm_HandSolder | F18: YAGEO | G18: RC1206JR-07100RL | H18: reichelt | I18: SMD 1/4W 100 | J18: https://www.reichelt.de/de/de/shop/produkt/smd-widerstand_1206_100_ohm_250_mw_5_-18242 | K18: 0.06 | L18: Stk | N18: RainDetector; SolarRadiation | O18: RainDetector R1; SolarRadiation R2 | P18: BOM_Mainboard.xlsx | Q18: OK | S18: =IF(G18<>"",UPPER(TRIM(G18)),UPPER(TRIM(C18&"|"&E18))) -> RC1206JR-07100RL
A19: ENP-00018 | B19: Widerstand | C19: SMD-Widerstand, 1206, 10 kOhm, 250 mW, 0,1% | D19: 10 kΩ, 0,1 %, 250 mW | E19: Resistor_SMD:R_1206_3216Metric_Pad1.30x1.75mm_HandSolder | F19: Panasonic | G19: ERA8AEB103V | H19: reichelt | I19: PAN ERA8AEB103V | J19: https://www.reichelt.de/de/de/shop/produkt/smd-widerstand_1206_10_kohm_250_mw_0_1_-238080 | K19: 0.75 | L19: Stk | N19: RainDetector | O19: R3 | P19: BOM_Mainboard.xlsx | Q19: OK | R19: Offensichtlich zusammengesetzte MPN aus Altdaten normalisiert. | S19: =IF(G19<>"",UPPER(TRIM(G19)),UPPER(TRIM(C19&"|"&E19))) -> ERA8AEB103V
A20: ENP-00019 | B20: Steckverbinder | C20: Stiftleiste, 8-polig, Raster 2,54mm | D20: 1x8, 2,54 mm | E20: Connector_PinHeader_2.54mm:PinHeader_1x08_P2.54mm_Vertical | F20: BKL Electronic | G20: 10120505 | H20: reichelt | I20: BKL 10120505 | J20: https://www.reichelt.de/de/de/shop/produkt/stiftleiste_8-polig_raster_2_54mm-235656 | K20: 0.31 | L20: Stk | N20: RainDetector | O20: J1,J2 | P20: BOM_Mainboard.xlsx | Q20: OK | S20: =IF(G20<>"",UPPER(TRIM(G20)),UPPER(TRIM(C20&"|"&E20))) -> 10120505
A21: ENP-00020 | B21: IC | C21: Timer-IC, Typ 555, SO-8 | D21: CMOS 555 | E21: Package_SO:SOIC-8_3.9x4.9mm_P1.27mm | F21: Renesas | G21: ICM7555IBAZ | H21: reichelt | I21: ICM 7555 IBAZ | J21: https://www.reichelt.de/de/de/shop/produkt/timer-ic_typ_555_so-8-188889 | K21: 1.1 | L21: Stk | N21: RainDetector | O21: U1 | P21: BOM_Mainboard.xlsx | Q21: OK | S21: =IF(G21<>"",UPPER(TRIM(G21)),UPPER(TRIM(C21&"|"&E21))) -> ICM7555IBAZ
A22: ENP-00021 | B22: Steckverbinder | C22: PinSocket 1x8, 2,54mm SMD | D22: 1x8, 2,54 mm, SMD | F22: fischer Elektronik | G22: BL 3 8 G | H22: reichelt | I22: FIS BL 3 8G | J22: https://www.reichelt.de/de/de/shop/produkt/buchsenleiste_1-reihig_1_x_8_-_2_54_mm-407106#open-modal-image-big-slider | K22: 1.7 | L22: Stk | N22: Detector | P22: BOM_Mainboard.xlsx | Q22: OK | S22: =IF(G22<>"",UPPER(TRIM(G22)),UPPER(TRIM(C22&"|"&E22))) -> BL 3 8 G
A23: ENP-00022 | B23: Widerstand | C23: SMD-Widerstand, 1206, 47 Ohm, 250 mW, 5% | D23: 47 Ω | E23: Resistor_SMD:R_1206_3216Metric_Pad1.30x1.75mm_HandSolder | F23: RND components | G23: RND 1551206S4J0470T5E | H23: reichelt | I23: RND 1551206 AF | J23: https://www.reichelt.de/de/de/shop/produkt/smd-widerstand_1206_47_ohm_250_mw_5_-250359 | K23: 0.02 | L23: Stk | N23: Detector | P23: BOM_Mainboard.xlsx | Q23: OK | S23: =IF(G23<>"",UPPER(TRIM(G23)),UPPER(TRIM(C23&"|"&E23))) -> RND 1551206S4J0470T5E
A24: ENP-00023 | B24: Relais | C24: Steck-Printrelais, 1 CO, 6 A, 5 V DC sensitiv | D24: 5 V, 1 Wechsler, 6 A | E24: Relay_THT:Relay_SPDT_Finder_34.51_Vertical | F24: finder | G24: 34.51.7.005.0010 | H24: reichelt | I24: FIN 34.51.7 5V | J24: https://www.reichelt.de/de/de/shop/produkt/steck-printrelais_1_co_6_a_5_v_dc_sensitiv-259179?PROVID=2788&gad_source=1&gad_campaignid=21154720511&gbraid=0AAAAADwnxtb50MtqKwtKae8MAeGQARqWX&gclid=CjwKCAjw7p_UBhBlEiwAhpIs72D6cK8XQyuxcrvb0uftoYY3618BT3lTyYSWWSou1J99G9udBcpsbhoCJbcQAvD_BwE | K24: 5.8 | L24: Stk | N24: DuoRelay | O24: K1,K2 | P24: BOM_Mainboard.xlsx | Q24: OK | S24: =IF(G24<>"",UPPER(TRIM(G24)),UPPER(TRIM(C24&"|"&E24))) -> 34.51.7.005.0010
A25: ENP-00024 | B25: IC | C25: I²C-EEPROM 2 Kbit mit vorprogrammierter EUI-64 und zwei Adresspins | D25: 2 Kbit, I²C, EUI-64, A0/A1, 1,7–5,5 V | E25: Package_TO_SOT_SMD:SOT-23-6 | F25: Microchip Technology | G25: 24AA025E64T-I/OT | L25: Stk | N25: EnvNode; EnvNodeMini Rev 0.2; Empty FullSize/HalfSize SMD/THT; DuoRelay; AnalogHydroPressure | O25: EnvNode U3; EnvNodeMini Rev 0.2 U2; Empty-Boards U1; DuoRelay U1; AnalogHydroPressure U1 | P25: KiCad; Microchip datasheet DS20002124G | Q25: OK | R25: Gemeinsamer Identifikations-EEPROM für alle Boards. Frühere Lieferantendaten gehörten zur falschen SPI-Version 25AA02E64T-I/OT und wurden entfernt; Bezugsquelle, Bestellnummer und Preis neu ergänzen. Auf Modulboards derzeit DNP.; In allen vier aktuellen Empty-Schemata derzeit DNP; A1 liegt an +3V3_SYS, A0 wird über J1 herausgeführt; U1 ist in den aktuellen DuoRelay- und AnalogHydroPressure-Schemata derzeit DNP | S25: =IF(G25<>"",UPPER(TRIM(G25)),UPPER(TRIM(C25&"|"&E25))) -> 24AA025E64T-I/OT
A26: ENP-00025 | B26: Steckverbinder | C26: JST-PH Stiftleiste, 4-polig, vertikal | D26: 4-polig, 2,00 mm | E26: Connector_JST:JST_PH_B4B-PH-K_1x04_P2.00mm_Vertical | F26: JST | G26: B4B-PH-K-S | H26: reichelt | I26: JST PH4P ST | J26: https://www.reichelt.de/de/de/shop/produkt/jst_-_stiftleiste_gerade_1x4-polig_-_ph-185051?PROVID=2788&gad_source=1&gad_campaignid=21154720511&gbraid=0AAAAADwnxtY1nWJSSrFeiIcYv9xLkqyFk&gclid=Cj0KCQjwnbrUBhDOARIsAKKhPpe2Az4gP1hQm4ZAaF5_8h_A8xPRV2yb28WCjCf626YJKTgCMxHQlnYaAjcNEALw_wcB | K26: 0.17 | L26: Stk | N26: EnvNode | O26: GPIO4, GPIO13-19, GPIO23, GPIO32-36, GPIO39 | P26: KiCad | Q26: OK | R26: Mögliche Überschneidung mit dem vorhandenen JST-PH-Set prüfen. | S26: =IF(G26<>"",UPPER(TRIM(G26)),UPPER(TRIM(C26&"|"&E26))) -> B4B-PH-K-S
A27: ENP-00026 | B27: Steckverbinder | C27: JST-SH Stiftleiste, 4-polig, horizontal | D27: 4-polig, 1,00 mm | E27: Connector_JST:JST_SH_SM04B-SRSS-TB_1x04-1MP_P1.00mm_Horizontal | F27: JST | G27: SM04B-SRSS-TB | H27: rs-online | I27: 515-1513 | J27: https://de.rs-online.com/web/p/leiterplatten-header/5151513?cm_mmc=DE-PLA-DS3A-_-google-_-CSS_DE_DE_PMAX_Catch+All-_--_-5151513&matchtype=&&gclsrc=aw.ds&gad_source=1&gad_campaignid=20579356490&gbraid=0AAAAADkeWNMTclazDyI9zcjcIGwAjXoW9&gclid=Cj0KCQjwnbrUBhDOARIsAKKhPpdLcMySAoEWll9Yd6dc_BCjxUsLFQOO7peTYM0DUy9ctvB7N_5s3bUaAoLZEALw_wcB | K27: 0.58 | L27: Stk | M27: 10 | N27: EnvNode; EnvNodeMini Rev 0.2; SolarRadiation | O27: EnvNode I2C0_1-3,I2C1_1-3; EnvNodeMini Rev 0.2 J4,J5; SolarRadiation I2C1 | P27: KiCad | Q27: OK | R27: MPN-Suffix und Verpackungsform festlegen; nicht mit Qwiic-Pigtail zusammenführen. | S27: =IF(G27<>"",UPPER(TRIM(G27)),UPPER(TRIM(C27&"|"&E27))) -> SM04B-SRSS-TB
A28: ENP-00027 | B28: IC | C28: 16-Bit ADC mit I²C | D28: ADS1115IDGS | E28: Package_SO:TSSOP-10_3x3mm_P0.5mm | F28: Texas Instruments | G28: ADS1115IDGS | L28: Stk | N28: AnalogInput; SolarRadiation; AnalogHydroPressure | O28: jeweils U1; AnalogHydroPressure U2 | P28: KiCad | Q28: OK | R28: Nicht mit dem vorhandenen ADS1115-Entwicklungsboard zusammenführen. | S28: =IF(G28<>"",UPPER(TRIM(G28)),UPPER(TRIM(C28&"|"&E28))) -> ADS1115IDGS
A29: ENP-00028 | B29: Kondensator | C29: Keramikkondensator 1 µF SMD | D29: 1 µF | E29: Capacitor_SMD:C_1206_3216Metric_Pad1.33x1.80mm_HandSolder | F29: Kyocera | G29: 12065C105JAT2A | H29: reichelt | I29: 12065C105JAT2A | J29: https://www.reichelt.de/de/de/shop/produkt/mlcc_1206_1_f_50_v_-5_x7r-409277 | K29: 0.16 | L29: Stk | N29: AnalogInput; AnalogHydroPressure | O29: C1; AnalogHydroPressure C4,C7 | P29: KiCad | Q29: OK | S29: =IF(G29<>"",UPPER(TRIM(G29)),UPPER(TRIM(C29&"|"&E29))) -> 12065C105JAT2A
A30: ENP-00029 | B30: Diode | C30: Dual-Schottky-Diode BAT54S | D30: BAT54S | E30: Package_TO_SOT_SMD:SOT-23 | F30: Diotec | G30: BAT54S | H30: reichelt | I30: BAT 54S DIO | J30: https://www.reichelt.de/de/de/shop/produkt/schottkydiode_30_v_0_2_a_sot-23-219176 | K30: 0.04 | L30: Stk | N30: AnalogInput; AnalogHydroPressure | O30: D1; AnalogHydroPressure D1 | P30: KiCad | Q30: OK | R30: Aktuelles AnalogHydroPressure verwendet SOT-23 und stimmt damit mit dem Artikel-Footprint überein; Gehäuse der bestellten Variante dennoch prüfen. | S30: =IF(G30<>"",UPPER(TRIM(G30)),UPPER(TRIM(C30&"|"&E30))) -> BAT54S
A31: ENP-00030 | B31: Steckverbinder | C31: Buchsenleiste 2x4, vertikal | D31: 2x4, 2,54 mm | E31: PinSocket_2x04_P2.54mm_Vertical / EnvNode Bottom-Variante | L31: Stk | N31: Legacy Rev 0.1: EnvNodeMini; AnalogInput; DuoRelay | O31: AnalogInput J1,J2; DuoRelay J1,J2; EnvNodeMini J1,J2,J4,J5 | P31: KiCad | Q31: Legacy | R31: Legacy-Artikel für die Modulsteckverbindung Rev 0.1; nicht für die aktuellen 2x7-Steckplätze verwenden. | S31: =IF(G31<>"",UPPER(TRIM(G31)),UPPER(TRIM(C31&"|"&E31))) -> BUCHSENLEISTE 2X4, VERTIKAL|PINSOCKET_2X04_P2.54MM_VERTICAL / ENVNODE BOTTOM-VARIANTE
A32: ENP-00031 | B32: Steckverbinder | C32: Buchsenleiste 1x2, vertikal | D32: 1x2, 2,54 mm | E32: Connector_PinSocket_2.54mm:PinSocket_1x02_P2.54mm_Vertical | L32: Stk | N32: AnalogInput; AnalogHydroPressure | O32: J3; AnalogHydroPressure J3 | P32: KiCad | Q32: Legacy | S32: =IF(G32<>"",UPPER(TRIM(G32)),UPPER(TRIM(C32&"|"&E32))) -> BUCHSENLEISTE 1X2, VERTIKAL|CONNECTOR_PINSOCKET_2.54MM:PINSOCKET_1X02_P2.54MM_VERTICAL
A33: ENP-00032 | B33: Widerstand | C33: Widerstand, Metallschicht, 150 Ohm, 0207, 250 mW, 0,1% | D33: 150 Ω, 0,1 %, ≤25 ppm/K, >0,125 W | E33: Resistor_THT:R_Axial_DIN0207_L6.3mm_D2.5mm_P7.62mm_Horizontal | F33: Arcol | G33: MRA0207 150R B 15PPM TA | H33: reichelt | I33: ARC MRA0207 150R | J33: https://www.reichelt.de/de/de/shop/produkt/widerstand_metallschicht_150_ohm_0207_250_mw_0_1_-237515 | K33: 1.3 | L33: Stk | N33: AnalogInput; AnalogHydroPressure | O33: R1; AnalogHydroPressure R3 | P33: KiCad | Q33: OK | S33: =IF(G33<>"",UPPER(TRIM(G33)),UPPER(TRIM(C33&"|"&E33))) -> MRA0207 150R B 15PPM TA
A34: ENP-00033 | B34: Diode | C34: Schnelle Schaltdiode 1N4148W | D34: 1N4148W | E34: Diode_SMD:D_SOD-123 | F34: Diotec | G34: 1N4148W | H34: reichelt | I34: 1N 4148W DIO | J34: https://www.reichelt.de/de/de/shop/produkt/kleinsignal-schalt-diode_100_v_150_ma_sod-123-219382 | K34: 0.02 | L34: Stk | N34: DuoRelay | O34: D1,D2 | P34: KiCad | Q34: OK | S34: =IF(G34<>"",UPPER(TRIM(G34)),UPPER(TRIM(C34&"|"&E34))) -> 1N4148W
A35: ENP-00034 | B35: Steckverbinder | C35: Schraubklemme 1x3, horizontal | D35: 3-polig, 5,08 mm | E35: TerminalBlock_Phoenix:TerminalBlock_Phoenix_MKDS-3-3-5.08_1x03_P5.08mm_Horizontal | F35: Phoenix Contact | L35: Stk | N35: DuoRelay | O35: J3,J4 | P35: KiCad | Q35: OK | R35: Exakte Hersteller-MPN ergänzen. | S35: =IF(G35<>"",UPPER(TRIM(G35)),UPPER(TRIM(C35&"|"&E35))) -> SCHRAUBKLEMME 1X3, HORIZONTAL|TERMINALBLOCK_PHOENIX:TERMINALBLOCK_PHOENIX_MKDS-3-3-5.08_1X03_P5.08MM_HORIZONTAL
A36: ENP-00035 | B36: Transistor | C36: NPN-Transistor BC817 | D36: BC817 | E36: Package_TO_SOT_SMD:SOT-23_Handsoldering | F36: Diotec | G36: BC817 | H36: reichelt | I36: BC 817-25 DIO | J36: https://www.reichelt.de/de/de/shop/produkt/bipolartransistor_npn_45v_0_5a_0_25w_sot-23-219186 | K36: 0.02 | L36: Stk | N36: DuoRelay | O36: Q1,Q2 | P36: KiCad | Q36: OK | S36: =IF(G36<>"",UPPER(TRIM(G36)),UPPER(TRIM(C36&"|"&E36))) -> BC817
A37: ENP-00036 | B37: Widerstand | C37: Widerstand 1 kΩ SMD | D37: 1 kΩ | E37: Resistor_SMD:R_1206_3216Metric_Pad1.30x1.75mm_HandSolder | F37: Vishay | G37: CRCW12061K00FKEA | H37: reichelt | I37: VIS CRCW12061K0 | J37: https://www.reichelt.de/de/de/shop/produkt/smd-widerstand_1206_1_0_kohm_250_mw_1_-238107?PROVID=2788&gad_source=1&gad_campaignid=1622074784&gbraid=0AAAAADwnxtbRDWe6ThqPkANhw_ak4jWBw&gclid=Cj0KCQjwnbrUBhDOARIsAKKhPpdctdiA6tqULvTn2sTUS6FqmJC1_J6HoVQmYOjjMGhSPlfi9dK4bSQaAmesEALw_wcB | K37: 0.14 | L37: Stk | N37: DuoRelay | O37: R1,R2 | P37: KiCad | Q37: OK | S37: =IF(G37<>"",UPPER(TRIM(G37)),UPPER(TRIM(C37&"|"&E37))) -> CRCW12061K00FKEA
A38: ENP-00037 | B38: Kondensator | C38: Elektrolytkondensator 47 µF radial | D38: 47 µF, 50 V | E38: Capacitor_SMD:CP_Elec_6.3x7.7 | F38: Europe ChemiCon | G38: HHXC500ARA470MHA0G | H38: reichelt | I38: ECC HXC500ARA470 | J38: https://www.reichelt.de/de/de/shop/produkt/elko_smd_47_f_50v_105_c_4000h_aec-q200-289252 | K38: 0.61 | L38: Stk | N38: EnvNodeMini Rev 0.1 | O38: EnvNodeMini Rev 0.1 C1 | P38: KiCad | Q38: OK | S38: =IF(G38<>"",UPPER(TRIM(G38)),UPPER(TRIM(C38&"|"&E38))) -> HHXC500ARA470MHA0G
A39: ENP-00038 | B39: Diode | C39: Schottky-Diode STPS3L60S | D39: B360B-13-F | E39: Diode_SMD:D_SMB_Handsoldering | F39: Diodes | G39: STPS3L60S | H39: reichelt | I39: B360B-13-F DII | J39: https://www.reichelt.de/de/de/shop/produkt/gleichrichterdiode_60_v_3_a_smb-216725 | K39: 0.25 | L39: Stk | N39: EnvNodeMini Rev 0.1 | O39: EnvNodeMini Rev 0.1 D1 | P39: KiCad | Q39: OK | S39: =IF(G39<>"",UPPER(TRIM(G39)),UPPER(TRIM(C39&"|"&E39))) -> STPS3L60S
A40: ENP-00039 | B40: Schutzdiode | C40: TVS-Diode SMBJ24A | D40: 24 V | E40: Diode_SMD:D_SMB_Handsoldering | F40: Littelfuse | G40: SMBJ24A | H40: reichelt | I40: P6SMB 24A SMD | J40: https://www.reichelt.de/de/de/shop/produkt/tvs-diode_unidirectional_24_v_600_w_do-214aa_smb-204320 | K40: 0.3 | L40: Stk | N40: EnvNodeMini Rev 0.1 | O40: EnvNodeMini Rev 0.1 D2 | P40: KiCad | Q40: OK | S40: =IF(G40<>"",UPPER(TRIM(G40)),UPPER(TRIM(C40&"|"&E40))) -> SMBJ24A
...

Sheet Kits
A1: Kit_ID | B1: Kit_Name | C1: Revision | D1: Status | E1: KiCad_Schematic | F1: KiCad_PCB | G1: Notes
A2: ENK-00001 | B2: EnvNode Mini Bausatz | C2: 0.2 | D2: Entwurf | E2: hardware/kicad/MainBoards/EnvNode Mini/EnvNode Mini.kicad_sch | F2: hardware/kicad/MainBoards/EnvNode Mini/EnvNode Mini.kicad_pcb | G2: Elektronischer Grundumfang vollständig aus aktuellem KiCad-Stand übernommen. Externe 5-V-Zuführung, Pigtail und weitere Montagekomponenten werden anschließend ergänzt.
A3: ENK-00002 | B3: DuoRelay FullSize Bausatz | C3: 0.2 | D3: Entwurf | E3: hardware/kicad/Modules/FullSize/DuoRelay/DuoRelay.kicad_sch | F3: hardware/kicad/Modules/FullSize/DuoRelay/DuoRelay.kicad_pcb | G3: Aktueller bestückter KiCad-Umfang plus PCB; DNP-Positionen enthalten und als DNP gekennzeichnet. Mechanische Zusatzteile können anschließend ergänzt werden.
A4: ENK-00003 | B4: AnalogHydroPressure FullSize Bausatz | C4: 0.2 | D4: Entwurf | E4: hardware/kicad/Modules/FullSize/AnalogHydroPressure/AnalogHydroPressure.kicad_sch | F4: hardware/kicad/Modules/FullSize/AnalogHydroPressure/AnalogHydroPressure.kicad_pcb | G4: Aktueller bestückter KiCad-Umfang einschließlich Busumschaltung plus PCB; DNP-Positionen enthalten und als DNP gekennzeichnet. Mechanische Zusatzteile können anschließend ergänzt werden.

Sheet Kit_BOM
A1: Kit_ID | B1: Kit_Revision | C1: Position | D1: RefDes | E1: Part_Number | F1: Quantity | G1: Build_Status | H1: Source_Type | I1: Value | J1: Footprint | K1: Unit_Price_EUR | L1: Position_Price_EUR | M1: Notes
A2: ENK-00001 | B2: 0.2 | C2: 10 | D2: C1 | E2: ENP-00006 | F2: 1 | G2: Bestücken | H2: KiCad | I2: =VLOOKUP(E2,Parts!$A$2:$S$200,4,FALSE) -> 100 nF, 10 %, X7R, 100 V | J2: =VLOOKUP(E2,Parts!$A$2:$S$200,5,FALSE) -> Capacitor_SMD:C_1206_3216Metric_Pad1.33x1.80mm_HandSolder | K2: 0.24 | L2: =IF(K2="","",F2*K2) -> 0.24 | M2: =VLOOKUP(E2,Parts!$A$2:$S$200,18,FALSE) -> Spannungsfestigkeit, Dielektrikum und Bauform vor Bestellung gegen Schaltplan und Footprint prüfen; C1 ist in allen vier aktuellen Empty-Schemata derzeit DNP; C1 ist im aktuellen DuoRelay-Schema derzeit DNP
A3: ENK-00001 | B3: 0.2 | C3: 20 | D3: C2 | E3: ENP-00007 | F3: 1 | G3: Bestücken | H3: KiCad | I3: =VLOOKUP(E3,Parts!$A$2:$S$200,4,FALSE) -> 10 µF, 25 V, X7R | J3: =VLOOKUP(E3,Parts!$A$2:$S$200,5,FALSE) -> Capacitor_SMD:C_1206_3216Metric_Pad1.33x1.80mm_HandSolder | K3: 0.11 | L3: =IF(K3="","",F3*K3) -> 0.11 | M3: =VLOOKUP(E3,Parts!$A$2:$S$200,18,FALSE) -> Spannungsfestigkeit, Dielektrikum und Bauform vor Bestellung gegen Schaltplan und Footprint prüfen
A4: ENK-00001 | B4: 0.2 | C4: 30 | D4: C3 | E4: ENP-00008 | F4: 1 | G4: Bestücken | H4: KiCad | I4: =VLOOKUP(E4,Parts!$A$2:$S$200,4,FALSE) -> 47 µF, 10 V | J4: =VLOOKUP(E4,Parts!$A$2:$S$200,5,FALSE) -> Capacitor_Tantalum_SMD:CP_EIA-3528-21_Kemet-B | K4: 0.29 | L4: =IF(K4="","",F4*K4) -> 0.29 | M4: =VLOOKUP(E4,Parts!$A$2:$S$200,18,FALSE) -> Polarisiert; Bauform B
A5: ENK-00001 | B5: 0.2 | C5: 40 | D5: C4 | E5: ENP-00006 | F5: 1 | G5: Bestücken | H5: KiCad | I5: =VLOOKUP(E5,Parts!$A$2:$S$200,4,FALSE) -> 100 nF, 10 %, X7R, 100 V | J5: =VLOOKUP(E5,Parts!$A$2:$S$200,5,FALSE) -> Capacitor_SMD:C_1206_3216Metric_Pad1.33x1.80mm_HandSolder | K5: 0.24 | L5: =IF(K5="","",F5*K5) -> 0.24 | M5: =VLOOKUP(E5,Parts!$A$2:$S$200,18,FALSE) -> Spannungsfestigkeit, Dielektrikum und Bauform vor Bestellung gegen Schaltplan und Footprint prüfen; C1 ist in allen vier aktuellen Empty-Schemata derzeit DNP; C1 ist im aktuellen DuoRelay-Schema derzeit DNP
A6: ENK-00001 | B6: 0.2 | C6: 50 | D6: C5 | E6: ENP-00006 | F6: 1 | G6: Bestücken | H6: KiCad | I6: =VLOOKUP(E6,Parts!$A$2:$S$200,4,FALSE) -> 100 nF, 10 %, X7R, 100 V | J6: =VLOOKUP(E6,Parts!$A$2:$S$200,5,FALSE) -> Capacitor_SMD:C_1206_3216Metric_Pad1.33x1.80mm_HandSolder | K6: 0.24 | L6: =IF(K6="","",F6*K6) -> 0.24 | M6: =VLOOKUP(E6,Parts!$A$2:$S$200,18,FALSE) -> Spannungsfestigkeit, Dielektrikum und Bauform vor Bestellung gegen Schaltplan und Footprint prüfen; C1 ist in allen vier aktuellen Empty-Schemata derzeit DNP; C1 ist im aktuellen DuoRelay-Schema derzeit DNP
A7: ENK-00001 | B7: 0.2 | C7: 60 | D7: C6 | E7: ENP-00056 | F7: 1 | G7: Bestücken | H7: KiCad | I7: =VLOOKUP(E7,Parts!$A$2:$S$200,4,FALSE) -> 10 µF, ±20 %, 25 V, 85 °C, 2000 h | J7: =VLOOKUP(E7,Parts!$A$2:$S$200,5,FALSE) -> Capacitor_SMD:CP_Elec_5x5.4 | K7: 0.18 | L7: =IF(K7="","",F7*K7) -> 0.18 | M7: =VLOOKUP(E7,Parts!$A$2:$S$200,18,FALSE) -> Panasonic SMD-Aluminium-Elektrolytkondensator, 10 µF ±20 %, 25 V, 85 °C, 2000 h. Abmessungen Ø 5,0 × 5,4 mm passen exakt zum zugewiesenen KiCad-Footprint. C6 liegt zwischen +3V3_SYS und GND; 25 V bieten deutliche Spannungsreserve. Polarität beachten.
A8: ENK-00001 | B8: 0.2 | C8: 70 | D8: D1 | E8: ENP-00055 | F8: 1 | G8: Bestücken | H8: KiCad | I8: =VLOOKUP(E8,Parts!$A$2:$S$200,4,FALSE) -> SS14, 1 A, 40 V, UF max. 0,5 V, IFSM 40 A | J8: =VLOOKUP(E8,Parts!$A$2:$S$200,5,FALSE) -> Diode_SMD:D_SMA | K8: 0.18 | L8: =IF(K8="","",F8*K8) -> 0.18 | M8: =VLOOKUP(E8,Parts!$A$2:$S$200,18,FALSE) -> Vishay Schottky-Gleichrichter im DO-214AC-/SMA-Gehäuse, 40 V Sperrspannung, 1 A Dauerstrom, 40 A Stoßstrom und Temperaturbereich −65 bis +150 °C. D1 entkoppelt +3V3_EXT, D2 entkoppelt +3V3_DEVKIT; beide speisen mit der Kathode +3V3_SYS. Zwei Stück je EnvNode Mini Rev 0.2.
A9: ENK-00001 | B9: 0.2 | C9: 80 | D9: D2 | E9: ENP-00055 | F9: 1 | G9: Bestücken | H9: KiCad | I9: =VLOOKUP(E9,Parts!$A$2:$S$200,4,FALSE) -> SS14, 1 A, 40 V, UF max. 0,5 V, IFSM 40 A | J9: =VLOOKUP(E9,Parts!$A$2:$S$200,5,FALSE) -> Diode_SMD:D_SMA | K9: 0.18 | L9: =IF(K9="","",F9*K9) -> 0.18 | M9: =VLOOKUP(E9,Parts!$A$2:$S$200,18,FALSE) -> Vishay Schottky-Gleichrichter im DO-214AC-/SMA-Gehäuse, 40 V Sperrspannung, 1 A Dauerstrom, 40 A Stoßstrom und Temperaturbereich −65 bis +150 °C. D1 entkoppelt +3V3_EXT, D2 entkoppelt +3V3_DEVKIT; beide speisen mit der Kathode +3V3_SYS. Zwei Stück je EnvNode Mini Rev 0.2.
A10: ENK-00001 | B10: 0.2 | C10: 90 | D10: J1 | E10: ENP-00012 | F10: 1 | G10: Bestücken | H10: KiCad | I10: =VLOOKUP(E10,Parts!$A$2:$S$200,4,FALSE) -> JST-PH, 2-polig, 2,00 mm | J10: =VLOOKUP(E10,Parts!$A$2:$S$200,5,FALSE) -> Connector_JST:JST_PH_B2B-PH-K_1x02_P2.00mm_Vertical | K10: 1.3 | L10: =IF(K10="","",F10*K10) -> 1.3 | M10: =VLOOKUP(E10,Parts!$A$2:$S$200,18,FALSE) -> 0
A11: ENK-00001 | B11: 0.2 | C11: 100 | D11: J2 | E11: ENP-00054 | F11: 1 | G11: Bestücken | H11: KiCad | I11: =VLOOKUP(E11,Parts!$A$2:$S$200,4,FALSE) -> 2x7, 2,54 mm, THT, vertikal, vergoldet, Bauhöhe 8,4 mm | J11: =VLOOKUP(E11,Parts!$A$2:$S$200,5,FALSE) -> Connector_PinSocket_2.54mm:PinSocket_2x07_P2.54mm_Vertical | K11: 0.56 | L11: =IF(K11="","",F11*K11) -> 0.56 | M11: =VLOOKUP(E11,Parts!$A$2:$S$200,18,FALSE) -> Würth WR-PHD Dual Socket Header, 14 Kontakte, 2,54 mm, THT, vergoldet, 3 A/250 V AC. Der generische KiCad-Footprint bildet Raster und THT-Anordnung ab; Gehäusekontur/Courtyard sind nicht herstellerspezifisch.
A12: ENK-00001 | B12: 0.2 | C12: 110 | D12: J3 | E12: ENP-00054 | F12: 1 | G12: Bestücken | H12: KiCad | I12: =VLOOKUP(E12,Parts!$A$2:$S$200,4,FALSE) -> 2x7, 2,54 mm, THT, vertikal, vergoldet, Bauhöhe 8,4 mm | J12: =VLOOKUP(E12,Parts!$A$2:$S$200,5,FALSE) -> Connector_PinSocket_2.54mm:PinSocket_2x07_P2.54mm_Vertical | K12: 0.56 | L12: =IF(K12="","",F12*K12) -> 0.56 | M12: =VLOOKUP(E12,Parts!$A$2:$S$200,18,FALSE) -> Würth WR-PHD Dual Socket Header, 14 Kontakte, 2,54 mm, THT, vergoldet, 3 A/250 V AC. Der generische KiCad-Footprint bildet Raster und THT-Anordnung ab; Gehäusekontur/Courtyard sind nicht herstellerspezifisch.
A13: ENK-00001 | B13: 0.2 | C13: 120 | D13: J4 | E13: ENP-00026 | F13: 1 | G13: Bestücken | H13: KiCad | I13: =VLOOKUP(E13,Parts!$A$2:$S$200,4,FALSE) -> 4-polig, 1,00 mm | J13: =VLOOKUP(E13,Parts!$A$2:$S$200,5,FALSE) -> Connector_JST:JST_SH_SM04B-SRSS-TB_1x04-1MP_P1.00mm_Horizontal | K13: 5.88 | L13: =IF(K13="","",F13*K13) -> 5.88 | M13: =VLOOKUP(E13,Parts!$A$2:$S$200,18,FALSE) -> MPN-Suffix und Verpackungsform festlegen; nicht mit Qwiic-Pigtail zusammenführen.
... A19: ENK-00001 | B19: 0.2 | C19: 180 | D19: U1 | E19: ENP-00010 | F19: 1 | G19: Bestücken | H19: KiCad | I19: =VLOOKUP(E19,Parts!$A$2:$S$200,4,FALSE) -> 38 Pin | J19: =VLOOKUP(E19,Parts!$A$2:$S$200,5,FALSE) -> PCM_Espressif:ESP32-DevKitC | K19: 5 | L19: =IF(K19="","",F19*K19) -> 5 | M19: =VLOOKUP(E19,Parts!$A$2:$S$200,18,FALSE) -> Exakte Modulvariante und Pinout vor Bestückung prüfen Hersteller/MPN aus verschobenen Altdaten korrigiert; genaue DevKitC-Variante fehlt.
A20: ENK-00001 | B20: 0.2 | C20: 190 | D20: U2 | E20: ENP-00024 | F20: 1 | G20: Bestücken | H20: KiCad | I20: =VLOOKUP(E20,Parts!$A$2:$S$200,4,FALSE) -> 2 Kbit, I²C, EUI-64, A0/A1, 1,7–5,5 V | J20: =VLOOKUP(E20,Parts!$A$2:$S$200,5,FALSE) -> Package_TO_SOT_SMD:SOT-23-6 | L20: =IF(K20="","",F20*K20) | M20: =VLOOKUP(E20,Parts!$A$2:$S$200,18,FALSE) -> Gemeinsamer Identifikations-EEPROM für alle Boards. Frühere Lieferantendaten gehörten zur falschen SPI-Version 25AA02E64T-I/OT und wurden entfernt; Bezugsquelle, Bestellnummer und Preis neu ergänzen. Auf Modulboards derzeit DNP.; In allen vier aktuellen Empty-Schemata derzeit DNP; A1 liegt an +3V3_SYS, A0 wird über J1 herausgeführt; U1 ist in den aktuellen DuoRelay- und AnalogHydroPressure-Schemata derzeit DNP
A21: ENK-00001 | B21: 0.2 | C21: 200 | D21: U3 | E21: ENP-00009 | F21: 1 | G21: Bestücken | H21: KiCad | I21: =VLOOKUP(E21,Parts!$A$2:$S$200,4,FALSE) -> 3,3 V, 1 A | J21: =VLOOKUP(E21,Parts!$A$2:$S$200,5,FALSE) -> Package_TO_SOT_SMD:SOT-223-3_TabPin2 | K21: 1 | L21: =IF(K21="","",F21*K21) -> 1 | M21: =VLOOKUP(E21,Parts!$A$2:$S$200,18,FALSE) -> Footprint und thermische Auslegung vor Bestückung prüfen
A22: ENK-00001 | B22: 0.2 | C22: 210 | E22: ENP-00057 | F22: 1 | G22: Bestücken | H22: PCB | I22: =VLOOKUP(E22,Parts!$A$2:$S$200,4,FALSE) -> Revision 0.2 | J22: =VLOOKUP(E22,Parts!$A$2:$S$200,5,FALSE) -> PCB: MainBoards/EnvNode Mini/EnvNode Mini.kicad_pcb | L22: =IF(K22="","",F22*K22) | M22: =VLOOKUP(E22,Parts!$A$2:$S$200,18,FALSE) -> Aktueller KiCad-Stand; Fertiger und konkrete Fertigungsvariante festlegen.
A23: ENK-00002 | B23: 0.2 | C23: 10 | D23: C1 | E23: ENP-00006 | F23: 1 | G23: DNP | H23: KiCad | I23: =VLOOKUP(E23,Parts!$A$2:$S$200,4,FALSE) -> 100 nF, 10 %, X7R, 100 V | J23: =VLOOKUP(E23,Parts!$A$2:$S$200,5,FALSE) -> Capacitor_SMD:C_1206_3216Metric_Pad1.33x1.80mm_HandSolder | K23: 0.24 | L23: =IF(K23="","",F23*K23) -> 0.24 | M23: =VLOOKUP(E23,Parts!$A$2:$S$200,18,FALSE) -> Spannungsfestigkeit, Dielektrikum und Bauform vor Bestellung gegen Schaltplan und Footprint prüfen; C1 ist in allen vier aktuellen Empty-Schemata derzeit DNP; C1 ist im aktuellen DuoRelay-Schema derzeit DNP
A24: ENK-00002 | B24: 0.2 | C24: 20 | D24: D1 | E24: ENP-00033 | F24: 1 | G24: Bestücken | H24: KiCad | I24: =VLOOKUP(E24,Parts!$A$2:$S$200,4,FALSE) -> 1N4148W | J24: =VLOOKUP(E24,Parts!$A$2:$S$200,5,FALSE) -> Diode_SMD:D_SOD-123 | K24: 0.02 | L24: =IF(K24="","",F24*K24) -> 0.02 | M24: =VLOOKUP(E24,Parts!$A$2:$S$200,18,FALSE) -> 0
A25: ENK-00002 | B25: 0.2 | C25: 30 | D25: D2 | E25: ENP-00033 | F25: 1 | G25: Bestücken | H25: KiCad | I25: =VLOOKUP(E25,Parts!$A$2:$S$200,4,FALSE) -> 1N4148W | J25: =VLOOKUP(E25,Parts!$A$2:$S$200,5,FALSE) -> Diode_SMD:D_SOD-123 | K25: 0.02 | L25: =IF(K25="","",F25*K25) -> 0.02 | M25: =VLOOKUP(E25,Parts!$A$2:$S$200,18,FALSE) -> 0
A26: ENK-00002 | B26: 0.2 | C26: 40 | D26: D3 | E26: ENP-00064 | F26: 1 | G26: Bestücken | H26: KiCad | I26: =VLOOKUP(E26,Parts!$A$2:$S$200,4,FALSE) -> Hyperrot, 645 nm, 250 mcd, 140°, Vf 2,0–2,5 V, IF max. 30 mA | J26: =VLOOKUP(E26,Parts!$A$2:$S$200,5,FALSE) -> LED_SMD:LED_1206_3216Metric_Pad1.42x1.75mm_HandSolder | K26: 0.11 | L26: =IF(K26="","",F26*K26) -> 0.11 | M26: =VLOOKUP(E26,Parts!$A$2:$S$200,18,FALSE) -> Kingbright SMD-LED im 1206-/3216-Gehäuse, hyperrot, 250 mcd, 140° Abstrahlwinkel, Bauhöhe 1,1 mm. Im DuoRelay liegen D3/D4 über je 1,5 kΩ an +5 V; bei etwa 2 V Vorwärtsspannung fließen rund 2 mA.
A27: ENK-00002 | B27: 0.2 | C27: 50 | D27: D4 | E27: ENP-00064 | F27: 1 | G27: Bestücken | H27: KiCad | I27: =VLOOKUP(E27,Parts!$A$2:$S$200,4,FALSE) -> Hyperrot, 645 nm, 250 mcd, 140°, Vf 2,0–2,5 V, IF max. 30 mA | J27: =VLOOKUP(E27,Parts!$A$2:$S$200,5,FALSE) -> LED_SMD:LED_1206_3216Metric_Pad1.42x1.75mm_HandSolder | K27: 0.11 | L27: =IF(K27="","",F27*K27) -> 0.11 | M27: =VLOOKUP(E27,Parts!$A$2:$S$200,18,FALSE) -> Kingbright SMD-LED im 1206-/3216-Gehäuse, hyperrot, 250 mcd, 140° Abstrahlwinkel, Bauhöhe 1,1 mm. Im DuoRelay liegen D3/D4 über je 1,5 kΩ an +5 V; bei etwa 2 V Vorwärtsspannung fließen rund 2 mA.
A28: ENK-00002 | B28: 0.2 | C28: 60 | D28: J1 | E28: ENP-00059 | F28: 1 | G28: Bestücken | H28: KiCad | I28: =VLOOKUP(E28,Parts!$A$2:$S$200,4,FALSE) -> 2x7, 2,54 mm, THT, vertikal, vergoldet, 6,1 mm Stecklänge, 3,0 mm Lötstift | J28: =VLOOKUP(E28,Parts!$A$2:$S$200,5,FALSE) -> EnvNode-Footprints:PinHeader_2x07_P2.54mm_Vertical_Bottom | K28: 0.3 | L28: =IF(K28="","",F28*K28) -> 0.3 | M28: =VLOOKUP(E28,Parts!$A$2:$S$200,18,FALSE) -> Standard-THT-Stiftleiste mit 11,6 mm Gesamtlänge, vergoldeten Kontakten und 3 A Nennstrom. Die Bestückung von der Modulunterseite und die dafür passende Pinorientierung werden durch den Projekt-Footprint PinHeader_2x07_P2.54mm_Vertical_Bottom festgelegt. Einzelpreis inkl. MwSt., Stand 2026-09-01; Preis und Verfügbarkeit vor Bestellung prüfen.
A29: ENK-00002 | B29: 0.2 | C29: 70 | D29: J3 | E29: ENP-00034 | F29: 1 | G29: Bestücken | H29: KiCad | I29: =VLOOKUP(E29,Parts!$A$2:$S$200,4,FALSE) -> 3-polig, 5,08 mm | J29: =VLOOKUP(E29,Parts!$A$2:$S$200,5,FALSE) -> TerminalBlock_Phoenix:TerminalBlock_Phoenix_MKDS-3-3-5.08_1x03_P5.08mm_Horizontal | L29: =IF(K29="","",F29*K29) | M29: =VLOOKUP(E29,Parts!$A$2:$S$200,18,FALSE) -> Exakte Hersteller-MPN ergänzen.
A30: ENK-00002 | B30: 0.2 | C30: 80 | D30: J4 | E30: ENP-00034 | F30: 1 | G30: Bestücken | H30: KiCad | I30: =VLOOKUP(E30,Parts!$A$2:$S$200,4,FALSE) -> 3-polig, 5,08 mm | J30: =VLOOKUP(E30,Parts!$A$2:$S$200,5,FALSE) -> TerminalBlock_Phoenix:TerminalBlock_Phoenix_MKDS-3-3-5.08_1x03_P5.08mm_Horizontal | L30: =IF(K30="","",F30*K30) | M30: =VLOOKUP(E30,Parts!$A$2:$S$200,18,FALSE) -> Exakte Hersteller-MPN ergänzen.
A31: ENK-00002 | B31: 0.2 | C31: 90 | D31: K1 | E31: ENP-00023 | F31: 1 | G31: Bestücken | H31: KiCad | I31: =VLOOKUP(E31,Parts!$A$2:$S$200,4,FALSE) -> 5 V, 1 Wechsler, 6 A | J31: =VLOOKUP(E31,Parts!$A$2:$S$200,5,FALSE) -> Relay_THT:Relay_SPDT_Finder_34.51_Vertical | K31: 5.8 | L31: =IF(K31="","",F31*K31) -> 5.8 | M31: =VLOOKUP(E31,Parts!$A$2:$S$200,18,FALSE) -> 0
A32: ENK-00002 | B32: 0.2 | C32: 100 | D32: K2 | E32: ENP-00023 | F32: 1 | G32: Bestücken | H32: KiCad | I32: =VLOOKUP(E32,Parts!$A$2:$S$200,4,FALSE) -> 5 V, 1 Wechsler, 6 A | J32: =VLOOKUP(E32,Parts!$A$2:$S$200,5,FALSE) -> Relay_THT:Relay_SPDT_Finder_34.51_Vertical | K32: 5.8 | L32: =IF(K32="","",F32*K32) -> 5.8 | M32: =VLOOKUP(E32,Parts!$A$2:$S$200,18,FALSE) -> 0
A33: ENK-00002 | B33: 0.2 | C33: 110 | D33: Q1 | E33: ENP-00035 | F33: 1 | G33: Bestücken | H33: KiCad | I33: =VLOOKUP(E33,Parts!$A$2:$S$200,4,FALSE) -> BC817 | J33: =VLOOKUP(E33,Parts!$A$2:$S$200,5,FALSE) -> Package_TO_SOT_SMD:SOT-23_Handsoldering | K33: 0.02 | L33: =IF(K33="","",F33*K33) -> 0.02 | M33: =VLOOKUP(E33,Parts!$A$2:$S$200,18,FALSE) -> 0
A34: ENK-00002 | B34: 0.2 | C34: 120 | D34: Q2 | E34: ENP-00035 | F34: 1 | G34: Bestücken | H34: KiCad | I34: =VLOOKUP(E34,Parts!$A$2:$S$200,4,FALSE) -> BC817 | J34: =VLOOKUP(E34,Parts!$A$2:$S$200,5,FALSE) -> Package_TO_SOT_SMD:SOT-23_Handsoldering | K34: 0.02 | L34: =IF(K34="","",F34*K34) -> 0.02 | M34: =VLOOKUP(E34,Parts!$A$2:$S$200,18,FALSE) -> 0
A35: ENK-00002 | B35: 0.2 | C35: 130 | D35: R1 | E35: ENP-00036 | F35: 1 | G35: Bestücken | H35: KiCad | I35: =VLOOKUP(E35,Parts!$A$2:$S$200,4,FALSE) -> 1 kΩ | J35: =VLOOKUP(E35,Parts!$A$2:$S$200,5,FALSE) -> Resistor_SMD:R_1206_3216Metric_Pad1.30x1.75mm_HandSolder | K35: 0.14 | L35: =IF(K35="","",F35*K35) -> 0.14 | M35: =VLOOKUP(E35,Parts!$A$2:$S$200,18,FALSE) -> 0
A36: ENK-00002 | B36: 0.2 | C36: 140 | D36: R2 | E36: ENP-00036 | F36: 1 | G36: Bestücken | H36: KiCad | I36: =VLOOKUP(E36,Parts!$A$2:$S$200,4,FALSE) -> 1 kΩ | J36: =VLOOKUP(E36,Parts!$A$2:$S$200,5,FALSE) -> Resistor_SMD:R_1206_3216Metric_Pad1.30x1.75mm_HandSolder | K36: 0.14 | L36: =IF(K36="","",F36*K36) -> 0.14 | M36: =VLOOKUP(E36,Parts!$A$2:$S$200,18,FALSE) -> 0
A37: ENK-00002 | B37: 0.2 | C37: 150 | D37: R3 | E37: ENP-00016 | F37: 1 | G37: Bestücken | H37: KiCad | I37: =VLOOKUP(E37,Parts!$A$2:$S$200,4,FALSE) -> 100 kΩ, 0,1 %, 250 mW | J37: =VLOOKUP(E37,Parts!$A$2:$S$200,5,FALSE) -> Resistor_SMD:R_1206_3216Metric_Pad1.30x1.75mm_HandSolder | K37: 0.83 | L37: =IF(K37="","",F37*K37) -> 0.83 | M37: =VLOOKUP(E37,Parts!$A$2:$S$200,18,FALSE) -> Lieferanten-Bestellnummer in der Altdatei enthält vermischte Angaben.
A38: ENK-00002 | B38: 0.2 | C38: 160 | D38: R4 | E38: ENP-00016 | F38: 1 | G38: Bestücken | H38: KiCad | I38: =VLOOKUP(E38,Parts!$A$2:$S$200,4,FALSE) -> 100 kΩ, 0,1 %, 250 mW | J38: =VLOOKUP(E38,Parts!$A$2:$S$200,5,FALSE) -> Resistor_SMD:R_1206_3216Metric_Pad1.30x1.75mm_HandSolder | K38: 0.83 | L38: =IF(K38="","",F38*K38) -> 0.83 | M38: =VLOOKUP(E38,Parts!$A$2:$S$200,18,FALSE) -> Lieferanten-Bestellnummer in der Altdatei enthält vermischte Angaben.
A39: ENK-00002 | B39: 0.2 | C39: 170 | D39: R5 | E39: ENP-00065 | F39: 1 | G39: Bestücken | H39: KiCad | I39: =VLOOKUP(E39,Parts!$A$2:$S$200,4,FALSE) -> 1,5 kΩ, 1 %, 0,25 W, 1206 | J39: =VLOOKUP(E39,Parts!$A$2:$S$200,5,FALSE) -> Resistor_SMD:R_1206_3216Metric_Pad1.30x1.75mm_HandSolder | K39: 0.14 | L39: =IF(K39="","",F39*K39) -> 0.14 | M39: =VLOOKUP(E39,Parts!$A$2:$S$200,18,FALSE) -> Exakt passend als Vorwiderstand der Relais-LEDs. Einzelpreis, Stand 2026-09-01; Preis und Verfügbarkeit vor Bestellung prüfen.
A40: ENK-00002 | B40: 0.2 | C40: 180 | D40: R6 | E40: ENP-00065 | F40: 1 | G40: Bestücken | H40: KiCad | I40: =VLOOKUP(E40,Parts!$A$2:$S$200,4,FALSE) -> 1,5 kΩ, 1 %, 0,25 W, 1206 | J40: =VLOOKUP(E40,Parts!$A$2:$S$200,5,FALSE) -> Resistor_SMD:R_1206_3216Metric_Pad1.30x1.75mm_HandSolder | K40: 0.14 | L40: =IF(K40="","",F40*K40) -> 0.14 | M40: =VLOOKUP(E40,Parts!$A$2:$S$200,18,FALSE) -> Exakt passend als Vorwiderstand der Relais-LEDs. Einzelpreis, Stand 2026-09-01; Preis und Verfügbarkeit vor Bestellung prüfen.
A41: ENK-00002 | B41: 0.2 | C41: 190 | D41: U1 | E41: ENP-00024 | F41: 1 | G41: DNP | H41: KiCad | I41: =VLOOKUP(E41,Parts!$A$2:$S$200,4,FALSE) -> 2 Kbit, I²C, EUI-64, A0/A1, 1,7–5,5 V | J41: =VLOOKUP(E41,Parts!$A$2:$S$200,5,FALSE) -> Package_TO_SOT_SMD:SOT-23-6 | L41: =IF(K41="","",F41*K41) | M41: =VLOOKUP(E41,Parts!$A$2:$S$200,18,FALSE) -> Gemeinsamer Identifikations-EEPROM für alle Boards. Frühere Lieferantendaten gehörten zur falschen SPI-Version 25AA02E64T-I/OT und wurden entfernt; Bezugsquelle, Bestellnummer und Preis neu ergänzen. Auf Modulboards derzeit DNP.; In allen vier aktuellen Empty-Schemata derzeit DNP; A1 liegt an +3V3_SYS, A0 wird über J1 herausgeführt; U1 ist in den aktuellen DuoRelay- und AnalogHydroPressure-Schemata derzeit DNP
A42: ENK-00002 | B42: 0.2 | C42: 200 | E42: ENP-00066 | F42: 1 | G42: Bestücken | H42: PCB | I42: =VLOOKUP(E42,Parts!$A$2:$S$200,4,FALSE) -> Revision 0.2 | J42: =VLOOKUP(E42,Parts!$A$2:$S$200,5,FALSE) -> PCB: Modules/FullSize/DuoRelay/DuoRelay.kicad_pcb | L42: =IF(K42="","",F42*K42) | M42: =VLOOKUP(E42,Parts!$A$2:$S$200,18,FALSE) -> Aktueller KiCad-Stand; Fertiger und konkrete Fertigungsvariante festlegen.
A43: ENK-00003 | B43: 0.2 | C43: 10 | D43: C1 | E43: ENP-00006 | F43: 1 | G43: DNP | H43: KiCad | I43: =VLOOKUP(E43,Parts!$A$2:$S$200,4,FALSE) -> 100 nF, 10 %, X7R, 100 V | J43: =VLOOKUP(E43,Parts!$A$2:$S$200,5,FALSE) -> Capacitor_SMD:C_1206_3216Metric_Pad1.33x1.80mm_HandSolder | K43: 0.24 | L43: =IF(K43="","",F43*K43) -> 0.24 | M43: =VLOOKUP(E43,Parts!$A$2:$S$200,18,FALSE) -> Spannungsfestigkeit, Dielektrikum und Bauform vor Bestellung gegen Schaltplan und Footprint prüfen; C1 ist in allen vier aktuellen Empty-Schemata derzeit DNP; C1 ist im aktuellen DuoRelay-Schema derzeit DNP
A44: ENK-00003 | B44: 0.2 | C44: 20 | D44: C3 | E44: ENP-00006 | F44: 1 | G44: Bestücken | H44: KiCad | I44: =VLOOKUP(E44,Parts!$A$2:$S$200,4,FALSE) -> 100 nF, 10 %, X7R, 100 V | J44: =VLOOKUP(E44,Parts!$A$2:$S$200,5,FALSE) -> Capacitor_SMD:C_1206_3216Metric_Pad1.33x1.80mm_HandSolder | K44: 0.24 | L44: =IF(K44="","",F44*K44) -> 0.24 | M44: =VLOOKUP(E44,Parts!$A$2:$S$200,18,FALSE) -> Spannungsfestigkeit, Dielektrikum und Bauform vor Bestellung gegen Schaltplan und Footprint prüfen; C1 ist in allen vier aktuellen Empty-Schemata derzeit DNP; C1 ist im aktuellen DuoRelay-Schema derzeit DNP
A45: ENK-00003 | B45: 0.2 | C45: 30 | D45: C4 | E45: ENP-00028 | F45: 1 | G45: Bestücken | H45: KiCad | I45: =VLOOKUP(E45,Parts!$A$2:$S$200,4,FALSE) -> 1 µF | J45: =VLOOKUP(E45,Parts!$A$2:$S$200,5,FALSE) -> Capacitor_SMD:C_1206_3216Metric_Pad1.33x1.80mm_HandSolder | K45: 0.16 | L45: =IF(K45="","",F45*K45) -> 0.16 | M45: =VLOOKUP(E45,Parts!$A$2:$S$200,18,FALSE) -> 0
...

Sheet Order_List
A1: Bestellliste für EnvNode-Bausätze
A2: Stückzahlen wählen; die Liste aggregiert gleiche Parts über alle Kits. DNP ist standardmäßig ausgeschlossen.
A4: Kit_ID | B4: Bausatz | C4: Stückzahl | E4: Option | F4: Auswahl
A5: ENK-00001 | B5: EnvNode Mini Bausatz | C5: 1 | E5: Optional bestellen | F5: Nein
A6: ENK-00002 | B6: DuoRelay FullSize Bausatz | C6: 2 | E6: DNP bestellen | F6: Ja
A7: ENK-00003 | B7: AnalogHydroPressure FullSize Bausatz | C7: 0
E8: Hinweis | F8: Bestellmenge wird bei hinterlegter Verpackungseinheit auf das nächste Vielfache aufgerundet.
A13: Part_ID | B13: Description | C13: Supplier | D13: Supplier_PN | E13: Bedarf | F13: Packaging_Unit | G13: Bestellmenge | H13: Unit_Price_EUR | I13: Bestellwert_EUR | J13: Import_Status | K13: URL
A14: ENP-00005 | B14: =IFERROR(VLOOKUP($A14,Parts!$A$2:$S$200,3,FALSE),"") -> 4.7 kOhm 1% SMD 1206 | C14: =IFERROR(VLOOKUP($A14,Parts!$A$2:$S$200,8,FALSE),"") -> reichelt | D14: =IFERROR(VLOOKUP($A14,Parts!$A$2:$S$200,9,FALSE),"") -> VIS CRCW12064K7 | E14: =SUMIFS(Kit_BOM!$F$2:$F$65,Kit_BOM!$E$2:$E$65,$A14,Kit_BOM!$A$2:$A$65,$A$5,Kit_BOM!$G$2:$G$65,"Bestücken")*$C$5+IF($F$5="Ja",SUMIFS(Kit_BOM!$F$2:$F$65,Kit_BOM!$E$2:$E$65,$A14,Kit_BOM!$A$2:$A$65,$A$5,Kit_BOM!$G$2:$G$65,"Optional")*$C$5,0)+IF($F$6="Ja",SUMIFS(Kit_BOM!$F$2:$F$65,Kit_BOM!$E$2:$E$65,$A14,Kit_BOM!$A$2:$A$65,$A$5,Kit_BOM!$G$2:$G$65,"DNP")*$C$5,0)+SUMIFS(Kit_BOM!$F$2:$F$65,Kit_BOM!$E$2:$E$65,$A14,Kit_BOM!$A$2:$A$65,$A$6,Kit_BOM!$G$2:$G$65,"Bestücken")*$C$6+IF($F$5="Ja",SUMIFS(Kit_BOM!$F$2:$F$65,Kit_BOM!$E$2:$E$65,$A14,Kit_BOM!$A$2:$A$65,$A$6,Kit_BOM!$G$2:$G$65,"Optional")*$C$6,0)+IF($F$6="Ja",SUMIFS(Kit_BOM!$F$2:$F$65,Kit_BOM!$E$2:$E$65,$A14,Kit_BOM!$A$2:$A$65,$A$6,Kit_BOM!$G$2:$G$65,"DNP")*$C$6,0)+SUMIFS(Kit_BOM!$F$2:$F$65,Kit_BOM!$E$2:$E$65,$A14,Kit_BOM!$A$2:$A$65,$A$7,Kit_BOM!$G$2:$G$65,"Bestücken")*$C$7+IF($F$5="Ja",SUMIFS(Kit_BOM!$F$2:$F$65,Kit_BOM!$E$2:$E$65,$A14,Kit_BOM!$A$2:$A$65,$A$7,Kit_BOM!$G$2:$G$65,"Optional")*$C$7,0)+IF($F$6="Ja",SUMIFS(Kit_BOM!$F$2:$F$65,Kit_BOM!$E$2:$E$65,$A14,Kit_BOM!$A$2:$A$65,$A$7,Kit_BOM!$G$2:$G$65,"DNP")*$C$7,0) -> 4 | F14: =IFERROR(VLOOKUP($A14,Parts!$A$2:$S$200,13,FALSE),"") -> 0 | G14: =IF($E14=0,0,IF(OR($F14="",$F14=0),$E14,CEILING($E14,$F14))) -> 4 | H14: =IFERROR(VLOOKUP($A14,Parts!$A$2:$S$200,11,FALSE),0) -> 0.15 | I14: =$G14*$H14 -> 0.6 | J14: =IF($E14=0,"Nicht benötigt",IF(LOWER($C14)<>"reichelt","Anderer Lieferant",IF($D14="","Supplier-PN fehlt","Reichelt bereit"))) -> Reichelt bereit | K14: =IFERROR(VLOOKUP($A14,Parts!$A$2:$S$200,10,FALSE),"") -> https://www.reichelt.de/de/de/shop/produkt/smd-widerstand_1206_4_7_kohm_250_mw_1_-238119
A15: ENP-00006 | B15: =IFERROR(VLOOKUP($A15,Parts!$A$2:$S$200,3,FALSE),"") -> 100 nF Keramik SMD | C15: =IFERROR(VLOOKUP($A15,Parts!$A$2:$S$200,8,FALSE),"") -> reichelt | D15: =IFERROR(VLOOKUP($A15,Parts!$A$2:$S$200,9,FALSE),"") -> KEM X7R1206A100N | E15: =SUMIFS(Kit_BOM!$F$2:$F$65,Kit_BOM!$E$2:$E$65,$A15,Kit_BOM!$A$2:$A$65,$A$5,Kit_BOM!$G$2:$G$65,"Bestücken")*$C$5+IF($F$5="Ja",SUMIFS(Kit_BOM!$F$2:$F$65,Kit_BOM!$E$2:$E$65,$A15,Kit_BOM!$A$2:$A$65,$A$5,Kit_BOM!$G$2:$G$65,"Optional")*$C$5,0)+IF($F$6="Ja",SUMIFS(Kit_BOM!$F$2:$F$65,Kit_BOM!$E$2:$E$65,$A15,Kit_BOM!$A$2:$A$65,$A$5,Kit_BOM!$G$2:$G$65,"DNP")*$C$5,0)+SUMIFS(Kit_BOM!$F$2:$F$65,Kit_BOM!$E$2:$E$65,$A15,Kit_BOM!$A$2:$A$65,$A$6,Kit_BOM!$G$2:$G$65,"Bestücken")*$C$6+IF($F$5="Ja",SUMIFS(Kit_BOM!$F$2:$F$65,Kit_BOM!$E$2:$E$65,$A15,Kit_BOM!$A$2:$A$65,$A$6,Kit_BOM!$G$2:$G$65,"Optional")*$C$6,0)+IF($F$6="Ja",SUMIFS(Kit_BOM!$F$2:$F$65,Kit_BOM!$E$2:$E$65,$A15,Kit_BOM!$A$2:$A$65,$A$6,Kit_BOM!$G$2:$G$65,"DNP")*$C$6,0)+SUMIFS(Kit_BOM!$F$2:$F$65,Kit_BOM!$E$2:$E$65,$A15,Kit_BOM!$A$2:$A$65,$A$7,Kit_BOM!$G$2:$G$65,"Bestücken")*$C$7+IF($F$5="Ja",SUMIFS(Kit_BOM!$F$2:$F$65,Kit_BOM!$E$2:$E$65,$A15,Kit_BOM!$A$2:$A$65,$A$7,Kit_BOM!$G$2:$G$65,"Optional")*$C$7,0)+IF($F$6="Ja",SUMIFS(Kit_BOM!$F$2:$F$65,Kit_BOM!$E$2:$E$65,$A15,Kit_BOM!$A$2:$A$65,$A$7,Kit_BOM!$G$2:$G$65,"DNP")*$C$7,0) -> 5 | F15: =IFERROR(VLOOKUP($A15,Parts!$A$2:$S$200,13,FALSE),"") -> 10 | G15: =IF($E15=0,0,IF(OR($F15="",$F15=0),$E15,CEILING($E15,$F15))) -> 10 | H15: =IFERROR(VLOOKUP($A15,Parts!$A$2:$S$200,11,FALSE),0) -> 0.24 | I15: =$G15*$H15 -> 2.4 | J15: =IF($E15=0,"Nicht benötigt",IF(LOWER($C15)<>"reichelt","Anderer Lieferant",IF($D15="","Supplier-PN fehlt","Reichelt bereit"))) -> Reichelt bereit | K15: =IFERROR(VLOOKUP($A15,Parts!$A$2:$S$200,10,FALSE),"") -> https://www.reichelt.de/de/de/shop/produkt/vielschicht_kerko_1206_100_nf_10_x7r_100_v_125_c-207151
A16: ENP-00007 | B16: =IFERROR(VLOOKUP($A16,Parts!$A$2:$S$200,3,FALSE),"") -> 10 uF Keramik SMD | C16: =IFERROR(VLOOKUP($A16,Parts!$A$2:$S$200,8,FALSE),"") -> reichelt | D16: =IFERROR(VLOOKUP($A16,Parts!$A$2:$S$200,9,FALSE),"") -> 12063C106KAT2A | E16: =SUMIFS(Kit_BOM!$F$2:$F$65,Kit_BOM!$E$2:$E$65,$A16,Kit_BOM!$A$2:$A$65,$A$5,Kit_BOM!$G$2:$G$65,"Bestücken")*$C$5+IF($F$5="Ja",SUMIFS(Kit_BOM!$F$2:$F$65,Kit_BOM!$E$2:$E$65,$A16,Kit_BOM!$A$2:$A$65,$A$5,Kit_BOM!$G$2:$G$65,"Optional")*$C$5,0)+IF($F$6="Ja",SUMIFS(Kit_BOM!$F$2:$F$65,Kit_BOM!$E$2:$E$65,$A16,Kit_BOM!$A$2:$A$65,$A$5,Kit_BOM!$G$2:$G$65,"DNP")*$C$5,0)+SUMIFS(Kit_BOM!$F$2:$F$65,Kit_BOM!$E$2:$E$65,$A16,Kit_BOM!$A$2:$A$65,$A$6,Kit_BOM!$G$2:$G$65,"Bestücken")*$C$6+IF($F$5="Ja",SUMIFS(Kit_BOM!$F$2:$F$65,Kit_BOM!$E$2:$E$65,$A16,Kit_BOM!$A$2:$A$65,$A$6,Kit_BOM!$G$2:$G$65,"Optional")*$C$6,0)+IF($F$6="Ja",SUMIFS(Kit_BOM!$F$2:$F$65,Kit_BOM!$E$2:$E$65,$A16,Kit_BOM!$A$2:$A$65,$A$6,Kit_BOM!$G$2:$G$65,"DNP")*$C$6,0)+SUMIFS(Kit_BOM!$F$2:$F$65,Kit_BOM!$E$2:$E$65,$A16,Kit_BOM!$A$2:$A$65,$A$7,Kit_BOM!$G$2:$G$65,"Bestücken")*$C$7+IF($F$5="Ja",SUMIFS(Kit_BOM!$F$2:$F$65,Kit_BOM!$E$2:$E$65,$A16,Kit_BOM!$A$2:$A$65,$A$7,Kit_BOM!$G$2:$G$65,"Optional")*$C$7,0)+IF($F$6="Ja",SUMIFS(Kit_BOM!$F$2:$F$65,Kit_BOM!$E$2:$E$65,$A16,Kit_BOM!$A$2:$A$65,$A$7,Kit_BOM!$G$2:$G$65,"DNP")*$C$7,0) -> 1 | F16: =IFERROR(VLOOKUP($A16,Parts!$A$2:$S$200,13,FALSE),"") -> 10 | G16: =IF($E16=0,0,IF(OR($F16="",$F16=0),$E16,CEILING($E16,$F16))) -> 10 | H16: =IFERROR(VLOOKUP($A16,Parts!$A$2:$S$200,11,FALSE),0) -> 0.11 | I16: =$G16*$H16 -> 1.1 | J16: =IF($E16=0,"Nicht benötigt",IF(LOWER($C16)<>"reichelt","Anderer Lieferant",IF($D16="","Supplier-PN fehlt","Reichelt bereit"))) -> Reichelt bereit | K16: =IFERROR(VLOOKUP($A16,Parts!$A$2:$S$200,10,FALSE),"") -> https://www.reichelt.de/de/de/shop/produkt/mlcc_1206_10_f_25_v_-10_x7r-409262
A17: ENP-00008 | B17: =IFERROR(VLOOKUP($A17,Parts!$A$2:$S$200,3,FALSE),"") -> 47 uF 10V Tantal | C17: =IFERROR(VLOOKUP($A17,Parts!$A$2:$S$200,8,FALSE),"") -> reichelt | D17: =IFERROR(VLOOKUP($A17,Parts!$A$2:$S$200,9,FALSE),"") -> TAJ 3528 47/10 | E17: =SUMIFS(Kit_BOM!$F$2:$F$65,Kit_BOM!$E$2:$E$65,$A17,Kit_BOM!$A$2:$A$65,$A$5,Kit_BOM!$G$2:$G$65,"Bestücken")*$C$5+IF($F$5="Ja",SUMIFS(Kit_BOM!$F$2:$F$65,Kit_BOM!$E$2:$E$65,$A17,Kit_BOM!$A$2:$A$65,$A$5,Kit_BOM!$G$2:$G$65,"Optional")*$C$5,0)+IF($F$6="Ja",SUMIFS(Kit_BOM!$F$2:$F$65,Kit_BOM!$E$2:$E$65,$A17,Kit_BOM!$A$2:$A$65,$A$5,Kit_BOM!$G$2:$G$65,"DNP")*$C$5,0)+SUMIFS(Kit_BOM!$F$2:$F$65,Kit_BOM!$E$2:$E$65,$A17,Kit_BOM!$A$2:$A$65,$A$6,Kit_BOM!$G$2:$G$65,"Bestücken")*$C$6+IF($F$5="Ja",SUMIFS(Kit_BOM!$F$2:$F$65,Kit_BOM!$E$2:$E$65,$A17,Kit_BOM!$A$2:$A$65,$A$6,Kit_BOM!$G$2:$G$65,"Optional")*$C$6,0)+IF($F$6="Ja",SUMIFS(Kit_BOM!$F$2:$F$65,Kit_BOM!$E$2:$E$65,$A17,Kit_BOM!$A$2:$A$65,$A$6,Kit_BOM!$G$2:$G$65,"DNP")*$C$6,0)+SUMIFS(Kit_BOM!$F$2:$F$65,Kit_BOM!$E$2:$E$65,$A17,Kit_BOM!$A$2:$A$65,$A$7,Kit_BOM!$G$2:$G$65,"Bestücken")*$C$7+IF($F$5="Ja",SUMIFS(Kit_BOM!$F$2:$F$65,Kit_BOM!$E$2:$E$65,$A17,Kit_BOM!$A$2:$A$65,$A$7,Kit_BOM!$G$2:$G$65,"Optional")*$C$7,0)+IF($F$6="Ja",SUMIFS(Kit_BOM!$F$2:$F$65,Kit_BOM!$E$2:$E$65,$A17,Kit_BOM!$A$2:$A$65,$A$7,Kit_BOM!$G$2:$G$65,"DNP")*$C$7,0) -> 1 | F17: =IFERROR(VLOOKUP($A17,Parts!$A$2:$S$200,13,FALSE),"") -> 0 | G17: =IF($E17=0,0,IF(OR($F17="",$F17=0),$E17,CEILING($E17,$F17))) -> 1 | H17: =IFERROR(VLOOKUP($A17,Parts!$A$2:$S$200,11,FALSE),0) -> 0.29 | I17: =$G17*$H17 -> 0.29 | J17: =IF($E17=0,"Nicht benötigt",IF(LOWER($C17)<>"reichelt","Anderer Lieferant",IF($D17="","Supplier-PN fehlt","Reichelt bereit"))) -> Reichelt bereit | K17: =IFERROR(VLOOKUP($A17,Parts!$A$2:$S$200,10,FALSE),"") -> https://www.reichelt.de/de/de/shop/produkt/smd-tantal_kondensator_47_f_10_v-167014
A18: ENP-00009 | B18: =IFERROR(VLOOKUP($A18,Parts!$A$2:$S$200,3,FALSE),"") -> LDO 3.3V SOT-223 | C18: =IFERROR(VLOOKUP($A18,Parts!$A$2:$S$200,8,FALSE),"") -> reichelt | D18: =IFERROR(VLOOKUP($A18,Parts!$A$2:$S$200,9,FALSE),"") -> LM 3940 IMP-3 | E18: =SUMIFS(Kit_BOM!$F$2:$F$65,Kit_BOM!$E$2:$E$65,$A18,Kit_BOM!$A$2:$A$65,$A$5,Kit_BOM!$G$2:$G$65,"Bestücken")*$C$5+IF($F$5="Ja",SUMIFS(Kit_BOM!$F$2:$F$65,Kit_BOM!$E$2:$E$65,$A18,Kit_BOM!$A$2:$A$65,$A$5,Kit_BOM!$G$2:$G$65,"Optional")*$C$5,0)+IF($F$6="Ja",SUMIFS(Kit_BOM!$F$2:$F$65,Kit_BOM!$E$2:$E$65,$A18,Kit_BOM!$A$2:$A$65,$A$5,Kit_BOM!$G$2:$G$65,"DNP")*$C$5,0)+SUMIFS(Kit_BOM!$F$2:$F$65,Kit_BOM!$E$2:$E$65,$A18,Kit_BOM!$A$2:$A$65,$A$6,Kit_BOM!$G$2:$G$65,"Bestücken")*$C$6+IF($F$5="Ja",SUMIFS(Kit_BOM!$F$2:$F$65,Kit_BOM!$E$2:$E$65,$A18,Kit_BOM!$A$2:$A$65,$A$6,Kit_BOM!$G$2:$G$65,"Optional")*$C$6,0)+IF($F$6="Ja",SUMIFS(Kit_BOM!$F$2:$F$65,Kit_BOM!$E$2:$E$65,$A18,Kit_BOM!$A$2:$A$65,$A$6,Kit_BOM!$G$2:$G$65,"DNP")*$C$6,0)+SUMIFS(Kit_BOM!$F$2:$F$65,Kit_BOM!$E$2:$E$65,$A18,Kit_BOM!$A$2:$A$65,$A$7,Kit_BOM!$G$2:$G$65,"Bestücken")*$C$7+IF($F$5="Ja",SUMIFS(Kit_BOM!$F$2:$F$65,Kit_BOM!$E$2:$E$65,$A18,Kit_BOM!$A$2:$A$65,$A$7,Kit_BOM!$G$2:$G$65,"Optional")*$C$7,0)+IF($F$6="Ja",SUMIFS(Kit_BOM!$F$2:$F$65,Kit_BOM!$E$2:$E$65,$A18,Kit_BOM!$A$2:$A$65,$A$7,Kit_BOM!$G$2:$G$65,"DNP")*$C$7,0) -> 1 | F18: =IFERROR(VLOOKUP($A18,Parts!$A$2:$S$200,13,FALSE),"") -> 3 | G18: =IF($E18=0,0,IF(OR($F18="",$F18=0),$E18,CEILING($E18,$F18))) -> 3 | H18: =IFERROR(VLOOKUP($A18,Parts!$A$2:$S$200,11,FALSE),0) -> 1 | I18: =$G18*$H18 -> 3 | J18: =IF($E18=0,"Nicht benötigt",IF(LOWER($C18)<>"reichelt","Anderer Lieferant",IF($D18="","Supplier-PN fehlt","Reichelt bereit"))) -> Reichelt bereit | K18: =IFERROR(VLOOKUP($A18,Parts!$A$2:$S$200,10,FALSE),"") -> https://www.reichelt.de/de/de/shop/produkt/ldo-spannungsregler_fix_3_3_vout_1_a_sot-223-109407?search=LM3940%2520&
A19: ENP-00010 | B19: =IFERROR(VLOOKUP($A19,Parts!$A$2:$S$200,3,FALSE),"") -> ESP32-DevKitC | C19: =IFERROR(VLOOKUP($A19,Parts!$A$2:$S$200,8,FALSE),"") -> 0 | D19: =IFERROR(VLOOKUP($A19,Parts!$A$2:$S$200,9,FALSE),"") -> 0 | E19: =SUMIFS(Kit_BOM!$F$2:$F$65,Kit_BOM!$E$2:$E$65,$A19,Kit_BOM!$A$2:$A$65,$A$5,Kit_BOM!$G$2:$G$65,"Bestücken")*$C$5+IF($F$5="Ja",SUMIFS(Kit_BOM!$F$2:$F$65,Kit_BOM!$E$2:$E$65,$A19,Kit_BOM!$A$2:$A$65,$A$5,Kit_BOM!$G$2:$G$65,"Optional")*$C$5,0)+IF($F$6="Ja",SUMIFS(Kit_BOM!$F$2:$F$65,Kit_BOM!$E$2:$E$65,$A19,Kit_BOM!$A$2:$A$65,$A$5,Kit_BOM!$G$2:$G$65,"DNP")*$C$5,0)+SUMIFS(Kit_BOM!$F$2:$F$65,Kit_BOM!$E$2:$E$65,$A19,Kit_BOM!$A$2:$A$65,$A$6,Kit_BOM!$G$2:$G$65,"Bestücken")*$C$6+IF($F$5="Ja",SUMIFS(Kit_BOM!$F$2:$F$65,Kit_BOM!$E$2:$E$65,$A19,Kit_BOM!$A$2:$A$65,$A$6,Kit_BOM!$G$2:$G$65,"Optional")*$C$6,0)+IF($F$6="Ja",SUMIFS(Kit_BOM!$F$2:$F$65,Kit_BOM!$E$2:$E$65,$A19,Kit_BOM!$A$2:$A$65,$A$6,Kit_BOM!$G$2:$G$65,"DNP")*$C$6,0)+SUMIFS(Kit_BOM!$F$2:$F$65,Kit_BOM!$E$2:$E$65,$A19,Kit_BOM!$A$2:$A$65,$A$7,Kit_BOM!$G$2:$G$65,"Bestücken")*$C$7+IF($F$5="Ja",SUMIFS(Kit_BOM!$F$2:$F$65,Kit_BOM!$E$2:$E$65,$A19,Kit_BOM!$A$2:$A$65,$A$7,Kit_BOM!$G$2:$G$65,"Optional")*$C$7,0)+IF($F$6="Ja",SUMIFS(Kit_BOM!$F$2:$F$65,Kit_BOM!$E$2:$E$65,$A19,Kit_BOM!$A$2:$A$65,$A$7,Kit_BOM!$G$2:$G$65,"DNP")*$C$7,0) -> 1 | F19: =IFERROR(VLOOKUP($A19,Parts!$A$2:$S$200,13,FALSE),"") -> 3 | G19: =IF($E19=0,0,IF(OR($F19="",$F19=0),$E19,CEILING($E19,$F19))) -> 3 | H19: =IFERROR(VLOOKUP($A19,Parts!$A$2:$S$200,11,FALSE),0) -> 5 | I19: =$G19*$H19 -> 15 | J19: =IF($E19=0,"Nicht benötigt",IF(LOWER($C19)<>"reichelt","Anderer Lieferant",IF($D19="","Supplier-PN fehlt","Reichelt bereit"))) -> Anderer Lieferant | K19: =IFERROR(VLOOKUP($A19,Parts!$A$2:$S$200,10,FALSE),"") -> 0
A20: ENP-00012 | B20: =IFERROR(VLOOKUP($A20,Parts!$A$2:$S$200,3,FALSE),"") -> JST - Stiftleiste, gerade, 1x2-polig - PH | C20: =IFERROR(VLOOKUP($A20,Parts!$A$2:$S$200,8,FALSE),"") -> reichelt | D20: =IFERROR(VLOOKUP($A20,Parts!$A$2:$S$200,9,FALSE),"") -> JST PH2P ST | E20: =SUMIFS(Kit_BOM!$F$2:$F$65,Kit_BOM!$E$2:$E$65,$A20,Kit_BOM!$A$2:$A$65,$A$5,Kit_BOM!$G$2:$G$65,"Bestücken")*$C$5+IF($F$5="Ja",SUMIFS(Kit_BOM!$F$2:$F$65,Kit_BOM!$E$2:$E$65,$A20,Kit_BOM!$A$2:$A$65,$A$5,Kit_BOM!$G$2:$G$65,"Optional")*$C$5,0)+IF($F$6="Ja",SUMIFS(Kit_BOM!$F$2:$F$65,Kit_BOM!$E$2:$E$65,$A20,Kit_BOM!$A$2:$A$65,$A$5,Kit_BOM!$G$2:$G$65,"DNP")*$C$5,0)+SUMIFS(Kit_BOM!$F$2:$F$65,Kit_BOM!$E$2:$E$65,$A20,Kit_BOM!$A$2:$A$65,$A$6,Kit_BOM!$G$2:$G$65,"Bestücken")*$C$6+IF($F$5="Ja",SUMIFS(Kit_BOM!$F$2:$F$65,Kit_BOM!$E$2:$E$65,$A20,Kit_BOM!$A$2:$A$65,$A$6,Kit_BOM!$G$2:$G$65,"Optional")*$C$6,0)+IF($F$6="Ja",SUMIFS(Kit_BOM!$F$2:$F$65,Kit_BOM!$E$2:$E$65,$A20,Kit_BOM!$A$2:$A$65,$A$6,Kit_BOM!$G$2:$G$65,"DNP")*$C$6,0)+SUMIFS(Kit_BOM!$F$2:$F$65,Kit_BOM!$E$2:$E$65,$A20,Kit_BOM!$A$2:$A$65,$A$7,Kit_BOM!$G$2:$G$65,"Bestücken")*$C$7+IF($F$5="Ja",SUMIFS(Kit_BOM!$F$2:$F$65,Kit_BOM!$E$2:$E$65,$A20,Kit_BOM!$A$2:$A$65,$A$7,Kit_BOM!$G$2:$G$65,"Optional")*$C$7,0)+IF($F$6="Ja",SUMIFS(Kit_BOM!$F$2:$F$65,Kit_BOM!$E$2:$E$65,$A20,Kit_BOM!$A$2:$A$65,$A$7,Kit_BOM!$G$2:$G$65,"DNP")*$C$7,0) -> 1 | F20: =IFERROR(VLOOKUP($A20,Parts!$A$2:$S$200,13,FALSE),"") -> 0 | G20: =IF($E20=0,0,IF(OR($F20="",$F20=0),$E20,CEILING($E20,$F20))) -> 1 | H20: =IFERROR(VLOOKUP($A20,Parts!$A$2:$S$200,11,FALSE),0) -> 1.3 | I20: =$G20*$H20 -> 1.3 | J20: =IF($E20=0,"Nicht benötigt",IF(LOWER($C20)<>"reichelt","Anderer Lieferant",IF($D20="","Supplier-PN fehlt","Reichelt bereit"))) -> Reichelt bereit | K20: =IFERROR(VLOOKUP($A20,Parts!$A$2:$S$200,10,FALSE),"") -> https://www.reichelt.de/de/de/shop/produkt/jst_-_stiftleiste_gerade_1x2-polig_-_ph-185049
